Workbook

Sheet CMG-PDO
A1: Fecha | B1: Hora | C1: Santa Rosa | D1: Trujillo | E1: Socabaya | F1: Campo Armiño
A2: 46049 | B2: 0.020833333 | C2: 29.4812 | D2: 30.2909 | E2: 31.6324 | F2: 27.831
A3: 46049 | B3: 0.041666667 | C3: 36.2344 | D3: 34.5705 | E3: 39.0389 | F3: 34.6662
A4: 46049 | B4: 0.0625 | C4: 29.6024 | D4: 30.3302 | E4: 31.7322 | F4: 27.9677
A5: 46049 | B5: 0.083333333 | C5: 29.3446 | D5: 30.0538 | E5: 31.4763 | F5: 27.7464
A6: 46049 | B6: 0.10416667 | C6: 23.722 | D6: 24.2775 | E6: 25.3849 | F6: 22.4376
A7: 46049 | B7: 0.125 | C7: 24.6024 | D7: 25.1689 | E7: 26.3647 | F7: 23.2804
A8: 46049 | B8: 0.14583333 | C8: 23.6809 | D8: 24.2108 | E8: 25.3742 | F8: 22.4148
A9: 46049 | B9: 0.16666667 | C9: 23.6818 | D9: 24.2062 | E9: 25.3967 | F9: 22.4192
A10: 46049 | B10: 0.1875 | C10: 23.6797 | D10: 24.205 | E10: 25.4255 | F10: 22.4174
A11: 46049 | B11: 0.20833333 | C11: 23.6793 | D11: 24.208 | E11: 25.3923 | F11: 22.4078
A12: 46049 | B12: 0.22916667 | C12: 36.0288 | D12: 36.9227 | E12: 38.7095 | F12: 34.083
A13: 46049 | B13: 0.25 | C13: 25.3252 | D13: 25.9608 | E13: 27.1055 | F13: 23.9571
... A50: 46050 | B50: 0.020833333 | C50: 29.5097 | D50: 30.3992 | E50: 31.4036 | F50: 27.763
A51: 46050 | B51: =+B50+1/48 -> 0.041666667 | C51: 36.5405 | D51: 37.5734 | E51: 38.9407 | F51: 34.3588
A52: 46050 | B52: =+B51+1/48 -> 0.0625 | C52: 29.5576 | D52: 30.4749 | E52: 31.456 | F52: 27.8278
A53: 46050 | B53: =+B52+1/48 -> 0.083333333 | C53: 24.5926 | D53: 25.3003 | E53: 26.1488 | F53: 23.1506
A54: 46050 | B54: =+B53+1/48 -> 0.10416667 | C54: 24.5829 | D54: 25.2837 | E54: 26.1449 | F54: 23.1462
A55: 46050 | B55: =+B54+1/48 -> 0.125 | C55: 24.5748 | D55: 25.2545 | E55: 26.1709 | F55: 23.1414
A56: 46050 | B56: =+B55+1/48 -> 0.14583333 | C56: 24.5773 | D56: 25.2462 | E56: 26.1475 | F56: 23.1363
A57: 46050 | B57: =+B56+1/48 -> 0.16666667 | C57: 24.5814 | D57: 25.2634 | E57: 26.1657 | F57: 23.1429
A58: 46050 | B58: =+B57+1/48 -> 0.1875 | C58: 24.5901 | D58: 25.2608 | E58: 26.2236 | F58: 23.1634
A59: 46050 | B59: =+B58+1/48 -> 0.20833333 | C59: 24.6056 | D59: 25.2977 | E59: 26.2461 | F59: 23.1797
A60: 46050 | B60: =+B59+1/48 -> 0.22916667 | C60: 29.7008 | D60: 30.6244 | E60: 31.698 | F60: 27.9512
A61: 46050 | B61: =+B60+1/48 -> 0.25 | C61: 28.6629 | D61: 29.5723 | E61: 30.5083 | F61: 26.9796
A62: 46050 | B62: =+B61+1/48 -> 0.27083333 | C62: 24.5974 | D62: 25.3844 | E62: 26.0748 | F62: 23.1383
... A97: 46050 | B97: =+B96+1/48 -> 1 | C97: 29.9643 | D97: 31.0952 | E97: 32.0371 | F97: 28.249
A98: =+A50+1 -> 46051 | B98: =+B97+1/48 -> 1.0208333 | C98: 32.5711 | D98: 33.6979 | E98: 34.1263 | F98: 31.0566
A99: =+A51+1 -> 46051 | B99: =+B98+1/48 -> 1.0416667 | C99: 32.7116 | D99: 33.7798 | E99: 34.2759 | F99: 31.1922
A100: =+A52+1 -> 46051 | B100: =+B99+1/48 -> 1.0625 | C100: 32.5513 | D100: 33.557 | E100: 34.0792 | F100: 31.0354
A101: =+A53+1 -> 46051 | B101: =+B100+1/48 -> 1.0833333 | C101: 32.4999 | D101: 33.583 | E101: 34.0022 | F101: 30.9922
A102: =+A54+1 -> 46051 | B102: =+B101+1/48 -> 1.1041667 | C102: 25.3637 | D102: 26.194 | E102: 26.5335 | F102: 24.1952
A103: =+A55+1 -> 46051 | B103: =+B102+1/48 -> 1.125 | C103: 25.3626 | D103: 26.1814 | E103: 26.546 | F103: 24.1974
A104: =+A56+1 -> 46051 | B104: =+B103+1/48 -> 1.1458333 | C104: 21.7885 | D104: 22.4838 | E104: 22.8259 | F104: 20.7964
A105: =+A57+1 -> 46051 | B105: =+B104+1/48 -> 1.1666667 | C105: 24.5434 | D105: 25.3374 | E105: 25.7066 | F105: 23.4297
A106: =+A58+1 -> 46051 | B106: =+B105+1/48 -> 1.1875 | C106: 25.3563 | D106: 26.1832 | E106: 26.5729 | F106: 24.2083
A107: =+A59+1 -> 46051 | B107: =+B106+1/48 -> 1.2083333 | C107: 25.3638 | D107: 26.1887 | E107: 26.5996 | F107: 24.2145
A108: =+A60+1 -> 46051 | B108: =+B107+1/48 -> 1.2291667 | C108: 32.4894 | D108: 33.5897 | E108: 34.0504 | F108: 30.9962
A109: =+A61+1 -> 46051 | B109: =+B108+1/48 -> 1.25 | C109: 25.4857 | D109: 26.3689 | E109: 26.6714 | F109: 24.3021
... A241: =+A193+1 -> 46053 | B241: =+B240+1/48 -> 4 | C241: 24.37 | D241: 25.3705 | E241: 26.0961 | F241: 23.4175

Sheet CMG-COS
A1: Fecha | B1: Hora | C1: Santa Rosa | D1: Trujillo | E1: Socabaya | F1: Campo Armiño
A2: 46049 | B2: 0.020833333 | C2: 30.8477 | D2: 31.8088 | E2: 33.2017 | F2: 29.1691
A3: 46049 | B3: 0.041666667 | C3: 25.3634 | D3: 26.2083 | E3: 27.3028 | F3: 23.9938
A4: 46049 | B4: 0.0625 | C4: 25.3008 | D4: 26.1177 | E4: 27.2469 | F4: 23.9428
A5: 46049 | B5: 0.083333333 | C5: 25.2057 | D5: 25.9798 | E5: 27.121 | F5: 23.8481
A6: 46049 | B6: 0.10416667 | C6: 25.1646 | D6: 25.9358 | E6: 27.0738 | F6: 23.8124
A7: 46049 | B7: 0.125 | C7: 25.1464 | D7: 25.9108 | E7: 27.091 | F7: 23.7989
A8: 46049 | B8: 0.14583333 | C8: 25.1332 | D8: 25.8803 | E8: 27.0752 | F8: 23.795
A9: 46049 | B9: 0.16666667 | C9: 25.2353 | D9: 25.9703 | E9: 27.1985 | F9: 23.8933
A10: 46049 | B10: 0.1875 | C10: 25.2823 | D10: 26.033 | E10: 27.2972 | F10: 23.9456
A11: 46049 | B11: 0.20833333 | C11: 25.2981 | D11: 26.0641 | E11: 27.3208 | F11: 23.9581
A12: 46049 | B12: 0.22916667 | C12: 25.29 | D12: 26.0918 | E12: 27.3087 | F12: 23.9517
A13: 46049 | B13: 0.25 | C13: 25.313 | D13: 26.1179 | E13: 27.1708 | F13: 23.9433
... A49: 46049 | B49: 1 | C49: 25.2451 | D49: 26.3107 | E49: 27.4698 | F49: 23.9681
A50: =+'CMG-PDO'!A50 -> 46050 | B50: =+'CMG-PDO'!B50 -> 0.020833333 | C50: 29.4119 | D50: 30.3479 | E50: 31.6598 | F50: 27.7661
A51: =+'CMG-PDO'!A51 -> 46050 | B51: =+'CMG-PDO'!B51 -> 0.041666667 | C51: 30.3097 | D51: 31.2038 | E51: 32.6192 | F51: 28.5904
A52: =+'CMG-PDO'!A52 -> 46050 | B52: =+'CMG-PDO'!B52 -> 0.0625 | C52: 30.2308 | D52: 31.2266 | E52: 32.5355 | F52: 28.5445
A53: =+'CMG-PDO'!A53 -> 46050 | B53: =+'CMG-PDO'!B53 -> 0.083333333 | C53: 24.5498 | D53: 25.3209 | E53: 26.404 | F53: 23.2011
A54: =+'CMG-PDO'!A54 -> 46050 | B54: =+'CMG-PDO'!B54 -> 0.10416667 | C54: 24.5409 | D54: 25.2962 | E54: 26.3917 | F54: 23.196
A55: =+'CMG-PDO'!A55 -> 46050 | B55: =+'CMG-PDO'!B55 -> 0.125 | C55: 24.5217 | D55: 25.27 | E55: 26.3907 | F55: 23.1765
A56: =+'CMG-PDO'!A56 -> 46050 | B56: =+'CMG-PDO'!B56 -> 0.14583333 | C56: 24.5129 | D56: 25.2436 | E56: 26.3571 | F56: 23.1599
A57: =+'CMG-PDO'!A57 -> 46050 | B57: =+'CMG-PDO'!B57 -> 0.16666667 | C57: 24.5229 | D57: 25.2722 | E57: 26.3896 | F57: 23.1749
A58: =+'CMG-PDO'!A58 -> 46050 | B58: =+'CMG-PDO'!B58 -> 0.1875 | C58: 23.6293 | D58: 24.3444 | E58: 25.476 | F58: 22.3447
A59: =+'CMG-PDO'!A59 -> 46050 | B59: =+'CMG-PDO'!B59 -> 0.20833333 | C59: 24.557 | D59: 25.3132 | E59: 26.478 | F59: 23.2212
A60: =+'CMG-PDO'!A60 -> 46050 | B60: =+'CMG-PDO'!B60 -> 0.22916667 | C60: 30.272 | D60: 31.3001 | E60: 32.7167 | F60: 28.6348
A61: =+'CMG-PDO'!A61 -> 46050 | B61: =+'CMG-PDO'!B61 -> 0.25 | C61: 29.5716 | D61: 30.6118 | E61: 31.7383 | F61: 27.9179
... A241: =+'CMG-PDO'!A241 -> 46053 | B241: =+'CMG-PDO'!B241 -> 4 | C241: 23.815 | D241: 24.7891 | E241: 25.5872 | F241: 22.9237

Sheet CMG-IEOD
A1: Fecha | B1: Hora | C1: Santa Rosa | D1: Trujillo | E1: Socabaya | F1: Campo Armiño
A2: 46049 | B2: 0.020833333 | C2: 36.836587 | D2: 37.952318 | E2: 38.598807 | F2: 34.874346
A3: 46049 | B3: 0.041666667 | C3: 36.855263 | D3: 37.850077 | E3: 38.637019 | F3: 34.933841
A4: 46049 | B4: 0.0625 | C4: 36.86364 | D4: 37.822244 | E4: 38.857389 | F4: 34.931901
A5: 46049 | B5: 0.083333333 | C5: 44.746504 | D5: 45.864652 | E5: 47.122006 | F5: 42.376352
A6: 46049 | B6: 0.10416667 | C6: 36.859503 | D6: 37.7848 | E6: 38.75779 | F6: 35.009501
A7: 46049 | B7: 0.125 | C7: 36.861549 | D7: 37.731434 | E7: 38.7903 | F7: 34.983705
A8: 46049 | B8: 0.14583333 | C8: 36.868023 | D8: 37.67159 | E8: 38.803266 | F8: 34.935267
A9: 46049 | B9: 0.16666667 | C9: 36.87578 | D9: 37.734762 | E9: 38.882779 | F9: 34.933086
A10: 46049 | B10: 0.1875 | C10: 36.865695 | D10: 37.681012 | E10: 38.858127 | F10: 35.044043
A11: 46049 | B11: 0.20833333 | C11: 36.880064 | D11: 37.674097 | E11: 38.864062 | F11: 35.007048
A12: 46049 | B12: 0.22916667 | C12: 36.864604 | D12: 37.743401 | E12: 38.766893 | F12: 34.967148
A13: 46049 | B13: 0.25 | C13: 36.837753 | D13: 37.744688 | E13: 38.609421 | F13: 34.858912
... A49: 46049 | B49: 1 | C49: 29.983273 | D49: 30.901212 | E49: 30.778709 | F49: 28.464131
A50: =+'CMG-PDO'!A50 -> 46050 | B50: =+'CMG-PDO'!B50 -> 0.020833333 | C50: 29.795092 | D50: 30.685684 | E50: 30.646358 | F50: 28.317245
A51: =+'CMG-PDO'!A51 -> 46050 | B51: =+'CMG-PDO'!B51 -> 0.041666667 | C51: 29.764856 | D51: 30.518673 | E51: 30.737001 | F51: 28.347473
A52: =+'CMG-PDO'!A52 -> 46050 | B52: =+'CMG-PDO'!B52 -> 0.0625 | C52: 29.845765 | D52: 30.589109 | E52: 30.755145 | F52: 28.394081
A53: =+'CMG-PDO'!A53 -> 46050 | B53: =+'CMG-PDO'!B53 -> 0.083333333 | C53: 25.635462 | D53: 26.305887 | E53: 26.455916 | F53: 24.431903
A54: =+'CMG-PDO'!A54 -> 46050 | B54: =+'CMG-PDO'!B54 -> 0.10416667 | C54: 25.458527 | D54: 26.234909 | E54: 26.247662 | F54: 24.230482
A55: =+'CMG-PDO'!A55 -> 46050 | B55: =+'CMG-PDO'!B55 -> 0.125 | C55: 25.541032 | D55: 26.282763 | E55: 26.357866 | F55: 24.34752
A56: =+'CMG-PDO'!A56 -> 46050 | B56: =+'CMG-PDO'!B56 -> 0.14583333 | C56: 25.587119 | D56: 26.311014 | E56: 26.553522 | F56: 24.403281
A57: =+'CMG-PDO'!A57 -> 46050 | B57: =+'CMG-PDO'!B57 -> 0.16666667 | C57: 25.597027 | D57: 26.282991 | E57: 26.603248 | F57: 24.426097
A58: =+'CMG-PDO'!A58 -> 46050 | B58: =+'CMG-PDO'!B58 -> 0.1875 | C58: 25.667593 | D58: 26.406743 | E58: 26.677385 | F58: 24.481522
A59: =+'CMG-PDO'!A59 -> 46050 | B59: =+'CMG-PDO'!B59 -> 0.20833333 | C59: 24.821878 | D59: 25.449132 | E59: 25.607793 | F59: 23.678901
A60: =+'CMG-PDO'!A60 -> 46050 | B60: =+'CMG-PDO'!B60 -> 0.22916667 | C60: 24.804746 | D60: 25.522794 | E60: 25.635663 | F60: 23.700737
A61: =+'CMG-PDO'!A61 -> 46050 | B61: =+'CMG-PDO'!B61 -> 0.25 | C61: 25.821371 | D61: 26.652105 | E61: 26.614826 | F61: 24.587393
... A145: =+'CMG-PDO'!A145 -> 46051 | B145: =+'CMG-PDO'!B145 -> 2 | C145: 30.330937 | D145: 31.451198 | E145: 31.274826 | F145: 28.855841

Sheet Hidro-ELP
A1: Fecha | B1: Hora | C1: La Mejorada Medido | D1: La Mejorada Proyección
A2: 46049 | B2: 0 | C2: 249.97 | D2: 263.69548
A3: 46049 | B3: 0.041666667 | C3: 248.41 | D3: 265.11385
A4: 46049 | B4: 0.083333333 | C4: 246.86 | D4: 264.80895
A5: 46049 | B5: 0.125 | C5: 246.86 | D5: 262.36784
A6: 46049 | B6: 0.16666667 | C6: 246.86 | D6: 258.7568
A7: 46049 | B7: 0.20833333 | C7: 245.31 | D7: 253.2591
A8: 46049 | B8: 0.25 | C8: 246.86 | D8: 249.35513
A9: 46049 | B9: 0.29166667 | C9: 246.86 | D9: 245.78942
A10: 46049 | B10: 0.33333333 | C10: 243.77 | D10: 246.85693
A11: 46049 | B11: 0.375 | C11: 245.31 | D11: 248.73075
A12: 46049 | B12: 0.41666667 | C12: 248.41 | D12: 250.37241
A13: 46049 | B13: 0.45833333 | C13: 245.31 | D13: 251.55766
... A25: 46049 | B25: 0.95833333 | C25: 230.15 | D25: 239.84656
A26: =+A2+1 -> 46050 | B26: =+B2 -> 0 | C26: 230.15 | D26: 240.96848
A27: =+A3+1 -> 46050 | B27: =+B3 -> 0.041666667 | C27: 230.15 | D27: 241.07389
A28: =+A4+1 -> 46050 | B28: =+B4 -> 0.083333333 | C28: 228.67 | D28: 239.57957
A29: =+A5+1 -> 46050 | B29: =+B5 -> 0.125 | C29: 225.71 | D29: 237.14149
A30: =+A6+1 -> 46050 | B30: =+B6 -> 0.16666667 | C30: 221.33 | D30: 232.43368
A31: =+A7+1 -> 46050 | B31: =+B7 -> 0.20833333 | C31: 219.88 | D31: 227.1349
A32: =+A8+1 -> 46050 | B32: =+B8 -> 0.25 | C32: 216.99 | D32: 224.16233
A33: =+A9+1 -> 46050 | B33: =+B9 -> 0.29166667 | C33: 216.99 | D33: 222.90099
A34: =+A10+1 -> 46050 | B34: =+B10 -> 0.33333333 | C34: 216.99 | D34: 223.9022
A35: =+A11+1 -> 46050 | B35: =+B11 -> 0.375 | C35: 218.43 | D35: 223.93299
A36: =+A12+1 -> 46050 | B36: =+B12 -> 0.41666667 | C36: 219.88 | D36: 221.98631
A37: =+A13+1 -> 46050 | B37: =+B13 -> 0.45833333 | C37: 216.99 | D37: 220.08828
... A155: =+A131+1 -> 46055 | B155: =+B131 -> 0.375 | C155: 687.29 | D155: 679.42472
A156: =+A132+1 -> 46055 | B156: =+B132 -> 0.41666667 | D156: 681.6941
A157: =+A133+1 -> 46055 | B157: =+B133 -> 0.45833333 | D157: 685.21279
A158: =+A134+1 -> 46055 | B158: =+B134 -> 0.5 | D158: 688.16255
A159: =+A135+1 -> 46055 | B159: =+B135 -> 0.54166667 | D159: 687.02783
A160: =+A136+1 -> 46055 | B160: =+B136 -> 0.58333333 | D160: 683.67923
A161: =+A137+1 -> 46055 | B161: =+B137 -> 0.625 | D161: 680.00209
A162: =+A138+1 -> 46055 | B162: =+B138 -> 0.66666667 | D162: 678.34695
A163: =+A139+1 -> 46055 | B163: =+B139 -> 0.70833333 | D163: 677.50701
A164: =+A140+1 -> 46055 | B164: =+B140 -> 0.75 | D164: 677.43604
A165: =+A141+1 -> 46055 | B165: =+B141 -> 0.79166667 | D165: 676.39864
A166: =+A142+1 -> 46055 | B166: =+B142 -> 0.83333333 | D166: 674.138
A167: =+A143+1 -> 46055 | B167: =+B143 -> 0.875 | D167: 670.27095
... A181: =+A157+1 -> 46056 | B181: =+B157 -> 0.45833333 | D181: 706.2147

Sheet Hoja de Trabajo
A1: ETAPA \ BARRA | B1: AGUAYTIA 220 | C1: BALNEARIO 220 | D1: BALNEARIOS 60 A | E1: CALLAHUANCA 220 | F1: CALLAHUANCA 60 | G1: CARHUAMAYO 220 | H1: CARHUAMAYO NUEVA 138 | I1: CARHUAQUERO 220 | J1: CHAVARRIA 220 A | K1: CHICLAYO OESTE 220 | L1: CHIMBOTE 220 | M1: GUADALUPE 220 | N1: HUACHIPA 60 | O1: HUACHO 220 | P1: HUANCAVELICA 220 | Q1: HUAYUCACHI 220 | R1: ICA 220 | S1: INDEPENDENCIA 220 | T1: MARCONA220 | U1: MOYOPAMPA 60 | V1: OROYA NUEVA 220 | W1: OROYA NUEVA 138 | X1: OROYA NUEVA 50 | Y1: PACHACHACA 220 | Z1: PARAGSHA2 220 | AA1: PARAGSHA 138 | AB1: PARAGSHA 50 | AC1: PARAMONGA NUEVA 220 | AD1: PIURA OESTE 220 | AE1: SAN JUAN 220 | AF1: SANTA ROSA 220 A | AG1: SANTA ROSA EDS 60 | AH1: TALARA 220 | AI1: TINGO MARIA 138 | AJ1: TINGO MARIA 220 | AK1: TRUJILLO 220 | AL1: VENTANILLA 220 | AM1: VIZCARRA 220 | AN1: ZAPALLAL 220 | AO1: AGUAYTIA 138 | AP1: PUCALLPA 138 | AQ1: HUALLANCA 138 | AR1: CHIMBOTE 138 | AS1: PUCALLPA 60 | AT1: ZORRITOS 220 | AU1: ABANCAY NUEVA 138 | AV1: ARICOTA138 | AW1: ARICOTA II 66 | AX1: CAMPO ARMINO 220 | AY1: AYAVIRI138 | AZ1: AZANGARO 138 | BA1: CACHIMAYO 138 | BB1: CALLALLI 138 | BC1: CERRO VERDE 138 | BD1: COMBAPATA 138 | BE1: DOLORESPATA 138 | BF1: DESIERTO220 | BG1: JULIACA 138 | BH1: MACHUPICCHU 138 | BI1: MOLLENDO 138 | BJ1: MOQUEGUA 220 | BK1: MOQUEGUA 138 | BL1: PUNO 220 | BM1: PUNO 138 | BN1: SANTUARIO 138 | BO1: SOCABAYA 220 | BP1: SOCABAYA 138 | BQ1: ILO 138 | BR1: LOS HEROES 220 A | BS1: LOS HEROES 66 | BT1: TINTAYA 138 | BU1: TOMASIRI 66 | BV1: REPARTICION 138 | BW1: ILO2 220 | BX1: COTARUSE 220 | BY1: CHILCA REP 220 | BZ1: CANTERA 220 | CA1: PIURA OESTE 60 | CB1: LA NINA 220 | CC1: CONOCOCHA 220 | CD1: HUINCO 220 | CE1: INDEPENDENCIA 60 | CF1: CHILLON 220 | CG1: CHILLON 60 | CH1: CHAVARRIA 60 A | CI1: CHAVARRIA 60 B | CJ1: BARSI 60 | CK1: BARSI 220 | CL1: OQUENDO 60 | CM1: CAJAMARCA 220 | CN1: PLANICIE 220 A | CO1: CARABAYLLO 220 | CP1: CARABAYLLO 500 | CQ1: CHILCA CTM 500 | CR1: CHILCA CTM 220 A | CS1: KIMAN AYLLU 138 | CT1: KIMAN AYLLU 220 | CU1: PARAMONGA EXISTENTE 138 | CV1: MACHALA 200 | CW1: CHIMBOTE 500 | CX1: TRUJILLO 500 | CY1: HUARANGAL 60 | CZ1: POMACOCHA 220 | DA1: PIEDRA BLANCA 138 | DB1: POROMA 220 | DC1: POROMA500 | DD1: OCONA 500 | DE1: MONTALVO 500 | DF1: MONTALVO 220 | DG1: HUANZA 220 | DH1: INDUSTRIALES 220 A | DI1: TINTAYA 220 | DJ1: LA NINA 500 | DK1: INDUSTRIALES 60 | DL1: CARHUAMAYO 50 | DM1: CARIPA138 | DN1: HUAMPANI 60 | DO1: HUANUCO 138 | DP1: REFINERIA ZINC 220 | DQ1: QUENCORO 138 | DR1: ILO 3 220 | DS1: MIRADOR 220 | DT1: MIRADOR 60 | DU1: ALTO PRADERA 220 | DV1: ABANCAY NUEVA 220 | DW1: LOMERA 220 | DX1: REQUE 220 | DY1: SAN JOSE 500 | DZ1: SANTA TERESA 220 | EA1: SURIRAY 220 | EB1: ASIA 220 | EC1: CERRO DEL AGUILA 220 | ED1: CHAGLLA 220 | EE1: RAMADA 220 | EF1: SANTA ROSA LDS 60 | EG1: LOMERA 60 | EH1: ZAPALLAL 60 | EI1: MALVINAS 220 | EJ1: MALVINAS 60 | EK1: ABANCAY 138 | EL1: YAUPI 138 | EM1: SANTA ISABEL 220 | EN1: YANANGO 220 | EO1: CHIMAY 220 | EP1: ILO3 138 | EQ1: MATUCANA 220 | ER1: COLCABAMBA 500 | ES1: COLCABAMBA 220 | ET1: YARABAMBA 500 | EU1: YARABAMBA 220 | EV1: BELAUNDE 220 | EW1: BELAUNDE 138 | EX1: CACLIC 220 | EY1: INDUSTRIALES 220B | EZ1: PLANICIE60 | FA1: COBRIZAI 69 | FB1: MOLLEPATA 60 | FC1: MOLLEPATA220 | FD1: CARAPONGO 500 | FE1: CARAPONGO 220 A | FF1: SAN JOSE 220 | FG1: MARCONA 60 A | FH1: SAN NICOLAS 60 | FI1: CALLAHUANCA EDN 220 | FJ1: PUMIRI138 | FK1: PUMIRI220 | FL1: SAN MIGUEL 220 | FM1: SAN MIGUEL 60 | FN1: FELAM 220 | FO1: MANCHAY 60 | FP1: MANCHAY 220 | FQ1: SAN RAFAEL 138 | FR1: SAN GABAN 138 | FS1: MARCONA 60 B | FT1: ANGEL 138 | FU1: PTO MALDONADO 138 | FV1: MEDIO MUNDO 220 | FW1: AUCAYACU 138 | FX1: BELLAVISTA 138 | FY1: TARAPOTO 138 | FZ1: PARINAS 220 | GA1: PAMPA HONDA 220 | GB1: ORCOTUNA 220 | GC1: SAN ROMAN 138 | GD1: SAN ROMAN 220 | GE1: CHILOTA 220 | GF1: MAZUCO 138 | GG1: JESUS 138 | GH1: CARHUAMAYO 138 | GI1: CINCO MANANTIALES 138 | GJ1: OXIDOS CERRO 138 | GK1: TOCACHE 138 | GL1: JUANJUI 138 | GM1: FRANCOISE 220 | GN1: BOTIFLACA 138 | GO1: MILL SITE 138 | GP1: PLAZA TOQUEPALA 138 | GQ1: QUEBRADA HONDA 138 | GR1: PANAMERICANA SOLAR 138 | GS1: TOQUEPALA 138 | GT1: ILO ELS 138 | GU1: REFINERIA 138 | GV1: LIXIVIACION 138 | GW1: PUSHBACK 138 | GX1: INTIPAMPA 138 | GY1: PLANICIE 220 B | GZ1: CHILCA CTM 220 B | HA1: CARAPONGO 220 B | HB1: CHILCA 1 220 | HC1: DERIVACION 220 | HD1: CHAVARRIA 220 B | HE1: DERIVACION 220 BARRA II | HF1: CAMPAS 220 | HG1: CAMPAS 500 | HH1: PLANICIE 500 | HI1: NUEVA CHINCHA 220 | HJ1: CAHUACHI 220 | HK1: VALLE DEL CHIRA 220 | HL1: SANTA ROSA 220 B | HM1: ERSUR 220 | HN1: FLAMENCO220 | HO1: BARRA3HERMANAS | HP1: BARRAPTALOMITAS | HQ1: PUERTO CHANCAY 220 | HR1: CHAPARRAL 138 | HS1: CHIRIBAMBA 220 | HT1: BARRAPTALOMITAS2 | HU1: YSHCAYUCRO 220 | HV1: PAQUILLUSI 220 | HW1: MIGUEL GRAU 500 | HX1: MIGUEL GRAU 220 | HY1: ALIPIO ROSALES 220 | HZ1: SUNNY | IA1: CUAJONE 138 | IB1: SAN MARTIN 220 | IC1: SAN LUIS 220 | ID1: CERRO VERDE 220
A2: 1 | B2: 23.9551 | C2: 23.6589 | D2: 23.6871 | E2: 23.3609 | F2: 22.807 | G2: 22.4283 | H2: 22.3145 | I2: 24.64 | J2: 23.9607 | K2: 25.2884 | L2: 24.5849 | M2: 25.1905 | N2: 24.0639 | O2: 23.3943 | P2: 23.2059 | Q2: 23.0613 | R2: 24.0976 | S2: 24.0793 | T2: 24.2825 | U2: 23.3513 | V2: 22.9329 | W2: 22.399 | X2: 22.6387 | Y2: 23.155 | Z2: 22.3997 | AA2: 22.6709 | AB2: 22.7246 | AC2: 23.4705 | AD2: 25.4704 | AE2: 23.6382 | AF2: 23.7613 | AG2: 23.7928 | AH2: 25.6737 | AI2: 23.7857 | AJ2: 23.7742 | AK2: 24.8868 | AL2: 23.9076 | AM2: 23.391 | AN2: 23.8689 | AO2: 24 | AP2: 24.8852 | AQ2: 23.3273 | AR2: 24.6547 | AS2: 24.9649 | AT2: 25.8687 | AU2: 23.7383 | AV2: 25.9702 | AW2: 25.9178 | AX2: 22.802 | AY2: 24.7358 | AZ2: 24.1957 | BA2: 24.497 | BB2: 25.6926 | BC2: 25.4923 | BD2: 25.1961 | BE2: 24.6111 | BF2: 24.0232 | BG2: 24.8548 | BH2: 23.3631 | BI2: 26.3851 | BJ2: 25.4535 | BK2: 25.4954 | BL2: 24.9133 | BM2: 24.9417 | BN2: 25.032 | BO2: 25.3056 | BP2: 25.3478 | BQ2: 26.0651 | BR2: 25.608 | BS2: 25.675 | BT2: 25.7432 | BU2: 25.8966 | BV2: 25.8534 | BW2: 25.4581 | BX2: 23.9652 | BY2: 23.3939 | BZ2: 23.8594 | CA2: 25.4976 | CB2: 25.2421 | CC2: 23.3777 | CD2: 23.5291 | CE2: 24.214 | CF2: 23.9144 | CG2: 23.9448 | CH2: 23.9896 | CI2: 24.027 | CJ2: 24.0462 | CK2: 24.0168 | CL2: 23.9893 | CM2: 24.6743 | CN2: 23.9648 | CO2: 23.8632 | CP2: 23.8298 | CQ2: 23.6755 | CR2: 23.5706 | CS2: 23.5852 | CT2: 23.8537 | CU2: 23.4262 | CV2: 0 | CW2: 24.5707 | CX2: 24.8367 | CY2: 23.945 | CZ2: 23.2489 | DA2: 23.6157 | DB2: 24.2856 | DC2: 24.2736 | DD2: 24.9264 | DE2: 25.3395 | DF2: 25.3955 | DG2: 23.5684 | DH2: 24.0412 | DI2: 25.5961 | DJ2: 25.2296 | DK2: 24.1797 | DL2: 22.3084 | DM2: 22.0839 | DN2: 24.6815 | DO2: 23.4314 | DP2: 23.8105 | DQ2: 24.6084 | DR2: 25.7399 | DS2: 23.9452 | DT2: 24.0081 | DU2: 23.5881 | DV2: 23.5765 | DW2: 23.6174 | DX2: 25.2731 | DY2: 25.2157 | DZ2: 23.3864 | EA2: 23.3925 | EB2: 23.6049 | EC2: 22.8822 | ED2: 21.0914 | EE2: 24.2419 | EF2: 23.7955 | EG2: 23.661 | EH2: 23.9674 | EI2: 24.0007 | EJ2: 24.0294 | EK2: 23.8558 | EL2: 21.9252 | EM2: 22.1127 | EN2: 23.2975 | EO2: 23.0817 | EP2: 25.7383 | EQ2: 23.1454 | ER2: 23.339 | ES2: 23.0941 | ET2: 25.2369 | EU2: 25.291 | EV2: 25.4132 | EW2: 25.5733 | EX2: 25.0733 | EY2: 23.7314 | EZ2: 24.3489 | FA2: 22.7267 | FB2: 23.5355 | FC2: 23.3445 | FD2: 23.7412 | FE2: 23.7324 | FF2: 25.2492 | FG2: 0 | FH2: 24.7502 | FI2: 23.3658 | FJ2: 24.2242 | FK2: 24.4566 | FL2: 23.7502 | FM2: 23.719 | FN2: 25.2917 | FO2: 24.1585 | FP2: 23.9709 | FQ2: 22.9134 | FR2: 21.1649 | FS2: 24.3572 | FT2: 21.1944 | FU2: 22.6789 | FV2: 23.4473 | FW2: 24.2648 | FX2: 26.3674 | FY2: 26.5251 | FZ2: 25.6707 | GA2: 24.3693 | GB2: 23.1362 | GC2: 24.8492 | GD2: 24.7962 | GE2: 25.2093 | GF2: 21.6497 | GG2: 25.2876 | GH2: 22.345 | GI2: 22.751 | GJ2: 22.6753 | GK2: 25.3076 | GL2: 26.215 | GM2: 22.4598 | GN2: 25.9228 | GO2: 26.0965 | GP2: 26.1044 | GQ2: 25.9886 | GR2: 25.7383 | GS2: 26.0918 | GT2: 25.985 | GU2: 26.1087 | GV2: 26.1063 | GW2: 26.0849 | GX2: 25.6617 | GY2: 23.9648 | GZ2: 23.5709 | HA2: 23.7326 | HB2: 0 | HC2: 23.8654 | HD2: 23.9624 | HE2: 23.8654 | HF2: 23.3857 | HG2: 23.434 | HH2: 23.8074 | HI2: 24.0948 | HJ2: 24.2058 | HK2: 25.6434 | HL2: 23.7611 | HM2: 24.1395 | HN2: 24.2826 | HO2: 24.1293 | HP2: 23.6511 | HQ2: 23.6944 | HR2: 26.0158 | HS2: 23.551 | HT2: 23.651 | HU2: 22.6997 | HV2: 23.1837 | HW2: 25.2919 | HX2: 25.3477 | HY2: 25.8371 | HZ2: 25.2492 | IA2: 25.8537 | IB2: 25.2492 | IC2: 25.4585 | ID2: 25.3859
A3: 2 | B3: 21.5303 | C3: 21.3536 | D3: 21.3775 | E3: 21.0952 | F3: 20.624 | G3: 20.2403 | H3: 20.129 | I3: 22.1302 | J3: 21.6069 | K3: 22.7043 | L3: 22.1181 | M3: 22.6257 | N3: 21.704 | O3: 21.0746 | P3: 20.9381 | Q3: 20.8192 | R3: 21.7518 | S3: 21.7333 | T3: 21.8892 | U3: 21.0583 | V3: 20.7407 | W3: 20.3745 | X3: 20.5623 | Y3: 20.917 | Z3: 20.2038 | AA3: 20.416 | AB3: 20.4588 | AC3: 21.1383 | AD3: 22.8719 | AE3: 21.3358 | AF3: 21.4425 | AG3: 21.4667 | AH3: 23.0466 | AI3: 21.3724 | AJ3: 21.3743 | AK3: 22.3733 | AL3: 21.5584 | AM3: 21.0628 | AN3: 21.5261 | AO3: 21.5691 | AP3: 22.3335 | AQ3: 20.9728 | AR3: 22.1786 | AS3: 22.4023 | AT3: 23.216 | AU3: 21.3555 | AV3: 23.3812 | AW3: 23.3353 | AX3: 20.5759 | AY3: 22.2499 | AZ3: 21.7593 | BA3: 22.0144 | BB3: 23.1247 | BC3: 22.9502 | BD3: 22.6461 | BE3: 22.1093 | BF3: 21.684 | BG3: 22.357 | BH3: 21.0293 | BI3: 23.7193 | BJ3: 22.9204 | BK3: 22.9575 | BL3: 22.4142 | BM3: 22.4393 | BN3: 22.5327 | BO3: 22.7875 | BP3: 22.8241 | BQ3: 23.4706 | BR3: 23.0546 | BS3: 23.1119 | BT3: 23.1639 | BU3: 23.3105 | BV3: 23.2593 | BW3: 22.9245 | BX3: 21.5866 | BY3: 21.1241 | BZ3: 21.5364 | CA3: 22.8945 | CB3: 22.6762 | CC3: 21.0496 | CD3: 21.289 | CE3: 21.8558 | CF3: 21.5643 | CG3: 21.5921 | CH3: 21.632 | CI3: 21.6643 | CJ3: 21.6808 | CK3: 21.6553 | CL3: 21.631 | CM3: 22.1679 | CN3: 21.6138 | CO3: 21.5233 | CP3: 21.4957 | CQ3: 21.3686 | CR3: 21.2796 | CS3: 21.2085 | CT3: 21.4502 | CU3: 21.097 | CV3: 0 | CW3: 22.1077 | CX3: 22.3319 | CY3: 21.5911 | CZ3: 20.9949 | DA3: 21.223 | DB3: 21.8928 | DC3: 21.8826 | DD3: 22.4567 | DE3: 22.8193 | DF3: 22.8691 | DG3: 21.3147 | DH3: 21.6794 | DI3: 23.0311 | DJ3: 22.6661 | DK3: 21.7998 | DL3: 20.1375 | DM3: 20.035 | DN3: 22.2482 | DO3: 21.0662 | DP3: 21.4878 | DQ3: 22.1066 | DR3: 23.1764 | DS3: 21.5934 | DT3: 21.6474 | DU3: 21.2931 | DV3: 21.2155 | DW3: 21.2807 | DX3: 22.6921 | DY3: 22.7107 | DZ3: 21.0506 | EA3: 21.0561 | EB3: 21.3114 | EC3: 20.6447 | ED3: 19.024 | EE3: 21.7908 | EF3: 21.4718 | EG3: 21.298 | EH3: 21.6109 | EI3: 21.6407 | EJ3: 21.6649 | EK3: 21.4572 | EL3: 19.7824 | EM3: 19.9538 | EN3: 21.025 | EO3: 20.8321 | EP3: 23.1754 | EQ3: 20.9004 | ER3: 21.0544 | ES3: 20.8359 | ET3: 22.7277 | EU3: 22.7747 | EV3: 22.7907 | EW3: 22.9251 | EX3: 22.5045 | EY3: 21.4166 | EZ3: 21.9422 | FA3: 20.5281 | FB3: 21.2092 | FC3: 21.0534 | FD3: 21.4205 | FE3: 21.4216 | FF3: 22.741 | FG3: 0 | FH3: 22.3049 | FI3: 21.0994 | FJ3: 21.7858 | FK3: 21.9985 | FL3: 21.4368 | FM3: 21.4109 | FN3: 22.7142 | FO3: 21.7792 | FP3: 21.619 | FQ3: 20.5811 | FR3: 19.0016 | FS3: 21.9551 | FT3: 19.0286 | FU3: 20.2917 | FV3: 21.1195 | FW3: 21.7896 | FX3: 23.6062 | FY3: 23.7313 | FZ3: 23.0439 | GA3: 21.9023 | GB3: 20.8922 | GC3: 22.3541 | GD3: 22.3065 | GE3: 22.6905 | GF3: 19.4113 | GG3: 22.7653 | GH3: 20.1595 | GI3: 20.5053 | GJ3: 20.4205 | GK3: 22.6969 | GL3: 23.4754 | GM3: 20.2579 | GN3: 23.337 | GO3: 23.4943 | GP3: 23.5015 | GQ3: 23.3982 | GR3: 23.1754 | GS3: 23.4901 | GT3: 23.3976 | GU3: 23.5096 | GV3: 23.5031 | GW3: 23.4836 | GX3: 23.106 | GY3: 21.6138 | GZ3: 21.2797 | HA3: 21.4218 | HB3: 0 | HC3: 21.5325 | HD3: 21.6084 | HE3: 21.5325 | HF3: 21.1022 | HG3: 21.1435 | HH3: 21.4787 | HI3: 21.7468 | HJ3: 21.8241 | HK3: 23.0225 | HL3: 21.4424 | HM3: 21.7604 | HN3: 21.8901 | HO3: 21.7511 | HP3: 21.3391 | HQ3: 21.36 | HR3: 23.3998 | HS3: 21.2522 | HT3: 21.339 | HU3: 20.4635 | HV3: 20.8535 | HW3: 22.7193 | HX3: 22.7671 | HY3: 23.1885 | HZ3: 22.741 | IA3: 23.2758 | IB3: 22.741 | IC3: 22.9253 | ID3: 22.8597
A4: 3 | B4: 23.5681 | C4: 23.3808 | D4: 23.4052 | E4: 23.1174 | F4: 22.6063 | G4: 22.1755 | H4: 22.0535 | I4: 24.2315 | J4: 23.6652 | K4: 24.8556 | L4: 24.2249 | M4: 24.7728 | N4: 23.7754 | O4: 23.0868 | P4: 22.9549 | Q4: 22.8147 | R4: 23.8762 | S4: 23.8356 | T4: 24.0207 | U4: 23.0689 | V4: 22.7248 | W4: 22.3193 | X4: 22.526 | Y4: 22.92 | Z4: 22.1354 | AA4: 22.3731 | AB4: 22.4213 | AC4: 23.1572 | AD4: 25.0429 | AE4: 23.3621 | AF4: 23.4915 | AG4: 23.5257 | AH4: 25.2329 | AI4: 23.3965 | AJ4: 23.4011 | AK4: 24.4991 | AL4: 23.6113 | AM4: 23.075 | AN4: 23.5751 | AO4: 23.6094 | AP4: 24.4247 | AQ4: 22.9704 | AR4: 24.2929 | AS4: 24.498 | AT4: 25.4152 | AU4: 23.4278 | AV4: 25.6603 | AW4: 25.6105 | AX4: 22.5544 | AY4: 24.4212 | AZ4: 23.8825 | BA4: 24.1513 | BB4: 25.3762 | BC4: 25.1782 | BD4: 24.8487 | BE4: 24.2548 | BF4: 23.7654 | BG4: 24.5329 | BH4: 23.069 | BI4: 26.0271 | BJ4: 25.1477 | BK4: 25.189 | BL4: 24.5953 | BM4: 24.6219 | BN4: 24.7156 | BO4: 24.9995 | BP4: 25.039 | BQ4: 25.7521 | BR4: 25.2956 | BS4: 25.3582 | BT4: 25.4251 | BU4: 25.5827 | BV4: 25.5196 | BW4: 25.1522 | BX4: 23.6803 | BY4: 23.1252 | BZ4: 23.5963 | CA4: 25.0673 | CB4: 24.83 | CC4: 23.0598 | CD4: 23.385 | CE4: 23.9721 | CF4: 23.6176 | CG4: 23.6481 | CH4: 23.692 | CI4: 23.7264 | CJ4: 23.7426 | CK4: 23.7164 | CL4: 23.6902 | CM4: 24.2754 | CN4: 23.6723 | CO4: 23.5721 | CP4: 23.5455 | CQ4: 23.4065 | CR4: 23.3042 | CS4: 23.229 | CT4: 23.4952 | CU4: 23.1134 | CV4: 0 | CW4: 24.2123 | CX4: 24.455 | CY4: 23.6438 | CZ4: 23.0047 | DA4: 23.2334 | DB4: 24.0139 | DC4: 24.0003 | DD4: 24.6347 | DE4: 25.0357 | DF4: 25.0908 | DG4: 23.3478 | DH4: 23.7431 | DI4: 25.2785 | DJ4: 24.8189 | DK4: 23.8744 | DL4: 22.0567 | DM4: 21.9492 | DN4: 24.3665 | DO4: 23.0624 | DP4: 23.5463 | DQ4: 24.2531 | DR4: 25.4308 | DS4: 23.644 | DT4: 23.6947 | DU4: 23.3132 | DV4: 23.2739 | DW4: 23.3102 | DX4: 24.8426 | DY4: 24.9155 | DZ4: 23.0924 | EA4: 23.0984 | EB4: 23.3352 | EC4: 22.6289 | ED4: 20.8428 | EE4: 23.8664 | EF4: 23.5228 | EG4: 23.3307 | EH4: 23.6674 | EI4: 23.6962 | EJ4: 23.7239 | EK4: 23.5401 | EL4: 21.6735 | EM4: 21.8615 | EN4: 23.0396 | EO4: 22.8281 | EP4: 25.4296 | EQ4: 22.904 | ER4: 23.0774 | ES4: 22.8384 | ET4: 24.934 | EU4: 24.9855 | EV4: 24.9455 | EW4: 25.0917 | EX4: 24.6363 | EY4: 23.4601 | EZ4: 24.0253 | FA4: 22.5028 | FB4: 23.2479 | FC4: 23.0794 | FD4: 23.4658 | FE4: 23.4764 | FF4: 24.9489 | FG4: 0 | FH4: 24.4565 | FI4: 23.122 | FJ4: 23.9113 | FK4: 24.1432 | FL4: 23.4925 | FM4: 23.4649 | FN4: 24.8716 | FO4: 23.8498 | FP4: 23.6778 | FQ4: 22.6041 | FR4: 20.8658 | FS4: 24.0915 | FT4: 20.8957 | FU4: 22.263 | FV4: 23.1366 | FW4: 23.8484 | FX4: 25.8259 | FY4: 25.9624 | FZ4: 25.2302 | GA4: 23.9876 | GB4: 22.8934 | GC4: 24.5298 | GD4: 24.478 | GE4: 24.8972 | GF4: 21.3096 | GG4: 24.9719 | GH4: 22.0866 | GI4: 22.4707 | GJ4: 22.378 | GK4: 24.833 | GL4: 25.6825 | GM4: 22.1937 | GN4: 25.6109 | GO4: 25.7846 | GP4: 25.7923 | GQ4: 25.6765 | GR4: 25.4296 | GS4: 25.7799 | GT4: 25.6725 | GU4: 25.7934 | GV4: 25.7941 | GW4: 25.7738 | GX4: 25.3538 | GY4: 23.6723 | GZ4: 23.3044 | HA4: 23.4765 | HB4: 0 | HC4: 23.6762 | HD4: 23.6668 | HE4: 23.6762 | HF4: 23.1242 | HG4: 23.1691 | HH4: 23.5263 | HI4: 23.8402 | HJ4: 23.9664 | HK4: 25.2073 | HL4: 23.4914 | HM4: 23.8819 | HN4: 24.0112 | HO4: 23.8772 | HP4: 23.4924 | HQ4: 23.3955 | HR4: 25.6746 | HS4: 23.3028 | HT4: 23.4923 | HU4: 22.4192 | HV4: 22.8866 | HW4: 24.8769 | HX4: 24.929 | HY4: 25.3856 | HZ4: 24.9489 | IA4: 25.5431 | IB4: 24.9489 | IC4: 25.1524 | ID4: 25.0787
A5: 4 | B5: 23.7007 | C5: 23.5055 | D5: 23.5282 | E5: 23.2725 | F5: 22.7709 | G5: 22.3134 | H5: 22.199 | I5: 24.3684 | J5: 23.8159 | K5: 24.993 | L5: 24.3597 | M5: 24.9099 | N5: 23.9323 | O5: 23.2274 | P5: 23.1107 | Q5: 22.9662 | R5: 24.0622 | S5: 24.0003 | T5: 24.2159 | U5: 23.2068 | V5: 22.8598 | W5: 22.4243 | X5: 22.6387 | Y5: 23.0639 | Z5: 22.274 | AA5: 22.5215 | AB5: 22.5696 | AC5: 23.2965 | AD5: 25.1808 | AE5: 23.4875 | AF5: 23.6328 | AG5: 23.6575 | AH5: 25.3711 | AI5: 23.5291 | AJ5: 23.5349 | AK5: 24.6348 | AL5: 23.761 | AM5: 23.2165 | AN5: 23.7241 | AO5: 23.7418 | AP5: 24.5529 | AQ5: 23.1024 | AR5: 24.4244 | AS5: 24.6259 | AT5: 25.5539 | AU5: 23.6037 | AV5: 25.8296 | AW5: 25.7785 | AX5: 22.7072 | AY5: 24.6203 | AZ5: 24.077 | BA5: 24.3394 | BB5: 25.5779 | BC5: 25.3703 | BD5: 25.0441 | BE5: 24.444 | BF5: 23.9163 | BG5: 24.7249 | BH5: 23.2417 | BI5: 26.2126 | BJ5: 25.3378 | BK5: 25.3792 | BL5: 24.7874 | BM5: 24.8137 | BN5: 24.906 | BO5: 25.1908 | BP5: 25.23 | BQ5: 25.9465 | BR5: 25.4833 | BS5: 25.5459 | BT5: 25.6315 | BU5: 25.7396 | BV5: 25.7123 | BW5: 25.3424 | BX5: 23.8564 | BY5: 23.2437 | BZ5: 23.7363 | CA5: 25.205 | CB5: 24.9687 | CC5: 23.1992 | CD5: 23.6391 | CE5: 24.137 | CF5: 23.7673 | CG5: 23.7984 | CH5: 23.8422 | CI5: 23.8759 | CJ5: 23.8918 | CK5: 23.8659 | CL5: 23.8399 | CM5: 24.415 | CN5: 23.8172 | CO5: 23.7216 | CP5: 23.694 | CQ5: 23.5521 | CR5: 23.4403 | CS5: 23.3671 | CT5: 23.6316 | CU5: 23.2523 | CV5: 0 | CW5: 24.349 | CX5: 24.5912 | CY5: 23.7917 | CZ5: 23.148 | DA5: 23.3665 | DB5: 24.1957 | DC5: 24.179 | DD5: 24.821 | DE5: 25.2255 | DF5: 25.2807 | DG5: 23.4979 | DH5: 23.8877 | DI5: 25.4826 | DJ5: 24.957 | DK5: 24.0194 | DL5: 22.2075 | DM5: 22.0649 | DN5: 24.5438 | DO5: 23.1975 | DP5: 23.7069 | DQ5: 24.4439 | DR5: 25.6157 | DS5: 23.7951 | DT5: 23.8525 | DU5: 23.4356 | DV5: 23.4484 | DW5: 23.4535 | DX5: 24.98 | DY5: 25.105 | DZ5: 23.2653 | EA5: 23.2713 | EB5: 23.4591 | EC5: 22.7827 | ED5: 20.9733 | EE5: 24.004 | EF5: 23.6635 | EG5: 23.47 | EH5: 23.8167 | EI5: 23.8457 | EJ5: 23.872 | EK5: 23.7163 | EL5: 21.807 | EM5: 21.997 | EN5: 23.191 | EO5: 22.9782 | EP5: 25.6136 | EQ5: 23.0579 | ER5: 23.2346 | ES5: 22.9936 | ET5: 25.1236 | EU5: 25.1766 | EV5: 25.0766 | EW5: 25.2225 | EX5: 24.7719 | EY5: 23.5976 | EZ5: 24.1608 | FA5: 22.6636 | FB5: 23.3968 | FC5: 23.233 | FD5: 23.6164 | FE5: 23.6388 | FF5: 25.1389 | FG5: 0 | FH5: 24.695 | FI5: 23.2773 | FJ5: 24.1056 | FK5: 24.3372 | FL5: 23.6546 | FM5: 23.6296 | FN5: 25.0132 | FO5: 23.9897 | FP5: 23.8225 | FQ5: 22.7946 | FR5: 21.0362 | FS5: 24.2909 | FT5: 21.0666 | FU5: 22.4216 | FV5: 23.2762 | FW5: 23.9788 | FX5: 25.9365 | FY5: 26.0723 | FZ5: 25.3686 | GA5: 24.1257 | GB5: 23.0447 | GC5: 24.7219 | GD5: 24.6706 | GE5: 25.0883 | GF5: 21.4741 | GG5: 25.162 | GH5: 22.2322 | GI5: 22.6212 | GJ5: 22.5266 | GK5: 24.9575 | GL5: 25.7953 | GM5: 22.3362 | GN5: 25.7945 | GO5: 25.9533 | GP5: 25.9617 | GQ5: 25.8546 | GR5: 25.6136 | GS5: 25.9487 | GT5: 25.8632 | GU5: 25.9904 | GV5: 25.9634 | GW5: 25.9332 | GX5: 25.538 | GY5: 23.8172 | GZ5: 23.4405 | HA5: 23.639 | HB5: 0 | HC5: 23.9006 | HD5: 23.8175 | HE5: 23.9006 | HF5: 23.2768 | HG5: 23.3222 | HH5: 23.673 | HI5: 23.9966 | HJ5: 24.1711 | HK5: 25.3454 | HL5: 23.6327 | HM5: 24.0787 | HN5: 24.1932 | HO5: 24.0781 | HP5: 23.7409 | HQ5: 23.5414 | HR5: 25.8651 | HS5: 23.4621 | HT5: 23.7408 | HU5: 22.5581 | HV5: 23.0705 | HW5: 25.0149 | HX5: 25.067 | HY5: 25.5243 | HZ5: 25.1389 | IA5: 25.7281 | IB5: 25.1389 | IC5: 25.3466 | ID5: 25.2717
A6: 5 | B6: 3.6474 | C6: 3.6189 | D6: 3.6219 | E6: 3.5918 | F6: 3.5173 | G6: 3.4399 | H6: 3.4212 | I6: 3.7508 | J6: 3.6713 | K6: 3.8474 | L6: 3.7536 | M6: 3.8359 | N6: 3.6892 | O6: 3.5798 | P6: 3.5634 | Q6: 3.5414 | R6: 3.7109 | S6: 3.6995 | T6: 3.7362 | U6: 3.5723 | V6: 3.5277 | W6: 3.4685 | X6: 3.4996 | Y6: 3.5577 | Z6: 3.4331 | AA6: 3.4691 | AB6: 3.4763 | AC6: 3.5898 | AD6: 3.8772 | AE6: 3.6162 | AF6: 3.6412 | AG6: 3.6439 | AH6: 3.9061 | AI6: 3.6209 | AJ6: 3.6226 | AK6: 3.7948 | AL6: 3.6631 | AM6: 3.5763 | AN6: 3.6586 | AO6: 3.6536 | AP6: 3.7745 | AQ6: 3.5578 | AR6: 3.7636 | AS6: 3.7854 | AT6: 3.9339 | AU6: 3.6361 | AV6: 3.9791 | AW6: 3.9711 | AX6: 3.5016 | AY6: 3.7906 | AZ6: 3.7061 | BA6: 3.7478 | BB6: 3.9405 | BC6: 3.9098 | BD6: 3.8568 | BE6: 3.7637 | BF6: 3.6849 | BG6: 3.807 | BH6: 3.5806 | BI6: 4.0365 | BJ6: 3.9045 | BK6: 3.9107 | BL6: 3.817 | BM6: 3.8209 | BN6: 3.8379 | BO6: 3.8824 | BP6: 3.8884 | BQ6: 3.996 | BR6: 3.9271 | BS6: 3.937 | BT6: 3.9475 | BU6: 3.9697 | BV6: 3.9617 | BW6: 3.9052 | BX6: 3.6759 | BY6: 3.5775 | BZ6: 3.6561 | CA6: 3.8808 | CB6: 3.8449 | CC6: 3.5739 | CD6: 3.6401 | CE6: 3.721 | CF6: 3.664 | CG6: 3.6688 | CH6: 3.6751 | CI6: 3.6801 | CJ6: 3.6829 | CK6: 3.6789 | CL6: 3.6749 | CM6: 3.758 | CN6: 3.6744 | CO6: 3.6586 | CP6: 3.6536 | CQ6: 3.6341 | CR6: 3.6136 | CS6: 3.598 | CT6: 3.639 | CU6: 3.5828 | CV6: 0 | CW6: 3.7518 | CX6: 3.7882 | CY6: 3.6689 | CZ6: 3.5692 | DA6: 3.5962 | DB6: 3.7321 | DC6: 3.729 | DD6: 3.8264 | DE6: 3.8875 | DF6: 3.8959 | DG6: 3.6238 | DH6: 3.6851 | DI6: 3.9246 | DJ6: 3.8432 | DK6: 3.7062 | DL6: 3.4223 | DM6: 3.4093 | DN6: 3.7855 | DO6: 3.5706 | DP6: 3.6551 | DQ6: 3.7638 | DR6: 3.9466 | DS6: 3.6695 | DT6: 3.6787 | DU6: 3.6077 | DV6: 3.6123 | DW6: 3.6153 | DX6: 3.8456 | DY6: 3.8694 | DZ6: 3.5843 | EA6: 3.5852 | EB6: 3.6116 | EC6: 3.5129 | ED6: 3.2326 | EE6: 3.6955 | EF6: 3.6458 | EG6: 3.6164 | EH6: 3.6717 | EI6: 3.6769 | EJ6: 3.6807 | EK6: 3.6535 | EL6: 3.3618 | EM6: 3.3911 | EN6: 3.5765 | EO6: 3.5434 | EP6: 3.9462 | EQ6: 3.5651 | ER6: 3.5825 | ES6: 3.5455 | ET6: 3.872 | EU6: 3.8803 | EV6: 3.8574 | EW6: 3.8794 | EX6: 3.8116 | EY6: 3.6352 | EZ6: 3.7284 | FA6: 3.4938 | FB6: 3.6075 | FC6: 3.5821 | FD6: 3.6416 | FE6: 3.6448 | FF6: 3.8747 | FG6: 0 | FH6: 3.8108 | FI6: 3.5926 | FJ6: 3.7106 | FK6: 3.747 | FL6: 3.6473 | FM6: 3.6427 | FN6: 3.8508 | FO6: 3.702 | FP6: 3.6752 | FQ6: 3.5048 | FR6: 3.2347 | FS6: 3.7479 | FT6: 3.2394 | FU6: 3.4429 | FV6: 3.5869 | FW6: 3.6892 | FX6: 3.9869 | FY6: 4.0062 | FZ6: 3.9058 | GA6: 3.7139 | GB6: 3.5535 | GC6: 3.8067 | GD6: 3.7987 | GE6: 3.8646 | GF6: 3.3004 | GG6: 3.8775 | GH6: 3.4264 | GI6: 3.4851 | GJ6: 3.4699 | GK6: 3.8378 | GL6: 3.9654 | GM6: 3.4424 | GN6: 3.9741 | GO6: 3.998 | GP6: 3.9992 | GQ6: 3.9831 | GR6: 3.9462 | GS6: 3.9973 | GT6: 3.9836 | GU6: 4.0021 | GV6: 3.9995 | GW6: 3.9947 | GX6: 3.9349 | GY6: 3.6744 | GZ6: 3.6137 | HA6: 3.6449 | HB6: 0 | HC6: 3.6893 | HD6: 3.6716 | HE6: 3.6893 | HF6: 3.5896 | HG6: 3.5961 | HH6: 3.6514 | HI6: 3.6981 | HJ6: 3.73 | HK6: 3.9025 | HL6: 3.6412 | HM6: 3.7156 | HN6: 3.7317 | HO6: 3.7159 | HP6: 3.6665 | HQ6: 3.6296 | HR6: 3.9846 | HS6: 3.6171 | HT6: 3.6665 | HU6: 3.4763 | HV6: 3.5519 | HW6: 3.852 | HX6: 3.86 | HY6: 3.9294 | HZ6: 3.8747 | IA6: 3.964 | IB6: 3.8747 | IC6: 3.9065 | ID6: 3.895
A7: 6 | B7: 21.4096 | C7: 21.2859 | D7: 21.3035 | E7: 21.1111 | F7: 20.6686 | G7: 20.2163 | H7: 20.1101 | I7: 22.0223 | J7: 21.5789 | K7: 22.5917 | L7: 22.0499 | M7: 22.529 | N7: 21.6904 | O7: 21.0374 | P7: 20.9437 | Q7: 20.8182 | R7: 21.8082 | S7: 21.7415 | T7: 21.9738 | U7: 21.0068 | V7: 20.7365 | W7: 20.3916 | X7: 20.5721 | Y7: 20.9141 | Z7: 20.1743 | AA7: 20.3849 | AB7: 20.426 | AC7: 21.0933 | AD7: 22.7651 | AE7: 21.271 | AF7: 21.4114 | AG7: 21.4279 | AH7: 22.9324 | AI7: 21.2554 | AJ7: 21.2674 | AK7: 22.2882 | AL7: 21.5302 | AM7: 21.0076 | AN7: 21.5043 | AO7: 21.4448 | AP7: 22.1386 | AQ7: 20.8974 | AR7: 22.1073 | AS7: 22.2009 | AT7: 23.0926 | AU7: 21.3701 | AV7: 23.4294 | AW7: 23.3852 | AX7: 20.5867 | AY7: 22.2872 | AZ7: 21.791 | BA7: 22.0256 | BB7: 23.1578 | BC7: 22.9926 | BD7: 22.6699 | BE7: 22.1179 | BF7: 21.6607 | BG7: 22.3856 | BH7: 21.0476 | BI7: 23.7502 | BJ7: 22.9668 | BK7: 23.0045 | BL7: 22.4461 | BM7: 22.4696 | BN7: 22.5636 | BO7: 22.8323 | BP7: 22.867 | BQ7: 23.5097 | BR7: 23.0975 | BS7: 23.1519 | BT7: 23.2086 | BU7: 23.3566 | BV7: 23.3 | BW7: 22.9709 | BX7: 21.6104 | BY7: 21.0523 | BZ7: 21.4964 | CA7: 22.7857 | CB7: 22.5784 | CC7: 20.9947 | CD7: 21.4314 | CE7: 21.8612 | CF7: 21.5356 | CG7: 21.5636 | CH7: 21.6011 | CI7: 21.6301 | CJ7: 21.6452 | CK7: 21.6222 | CL7: 21.5992 | CM7: 22.0641 | CN7: 21.5975 | CO7: 21.5046 | CP7: 21.4783 | CQ7: 21.3686 | CR7: 21.254 | CS7: 21.1322 | CT7: 21.3706 | CU7: 21.0528 | CV7: 0 | CW7: 22.04 | CX7: 22.2502 | CY7: 21.5629 | CZ7: 20.9834 | DA7: 21.112 | DB7: 21.9482 | DC7: 21.93 | DD7: 22.5043 | DE7: 22.8652 | DF7: 22.9154 | DG7: 21.3013 | DH7: 21.6594 | DI7: 23.0747 | DJ7: 22.5686 | DK7: 21.7811 | DL7: 20.1204 | DM7: 20.0486 | DN7: 22.2484 | DO7: 20.9648 | DP7: 21.49 | DQ7: 22.1196 | DR7: 23.2221 | DS7: 21.5669 | DT7: 21.6198 | DU7: 21.2237 | DV7: 21.232 | DW7: 21.2492 | DX7: 22.582 | DY7: 22.7577 | DZ7: 21.069 | EA7: 21.0745 | EB7: 21.2457 | EC7: 20.6545 | ED7: 18.9958 | EE7: 21.6986 | EF7: 21.4378 | EG7: 21.2614 | EH7: 21.5802 | EI7: 21.6087 | EJ7: 21.63 | EK7: 21.47 | EL7: 19.7569 | EM7: 19.9293 | EN7: 21.0273 | EO7: 20.8325 | EP7: 23.221 | EQ7: 20.9404 | ER7: 21.0642 | ES7: 20.8458 | ET7: 22.7723 | EU7: 22.8198 | EV7: 22.6335 | EW7: 22.7608 | EX7: 22.3708 | EY7: 21.3774 | EZ7: 21.8994 | FA7: 20.5711 | FB7: 21.1717 | FC7: 21.0431 | FD7: 21.4101 | FE7: 21.4312 | FF7: 22.7892 | FG7: 0 | FH7: 22.4074 | FI7: 21.1156 | FJ7: 21.8178 | FK7: 22.0316 | FL7: 21.4454 | FM7: 21.4219 | FN7: 22.613 | FO7: 21.7516 | FP7: 21.6021 | FQ7: 20.5965 | FR7: 19.0066 | FS7: 22.0411 | FT7: 19.0341 | FU7: 20.213 | FV7: 21.0775 | FW7: 21.6527 | FX7: 23.3791 | FY7: 23.4939 | FZ7: 22.9301 | GA7: 21.8064 | GB7: 20.8894 | GC7: 22.3847 | GD7: 22.3377 | GE7: 22.7293 | GF7: 19.3873 | GG7: 22.8005 | GH7: 20.1413 | GI7: 20.4823 | GJ7: 20.3898 | GK7: 22.515 | GL7: 23.2541 | GM7: 20.2282 | GN7: 23.3864 | GO7: 23.5422 | GP7: 23.5494 | GQ7: 23.446 | GR7: 23.221 | GS7: 23.538 | GT7: 23.4372 | GU7: 23.5454 | GV7: 23.551 | GW7: 23.5309 | GX7: 23.1532 | GY7: 21.5975 | GZ7: 21.2541 | HA7: 21.4313 | HB7: 0 | HC7: 21.6962 | HD7: 21.5803 | HE7: 21.6962 | HF7: 21.1048 | HG7: 21.1433 | HH7: 21.4663 | HI7: 21.7342 | HJ7: 21.9377 | HK7: 22.9119 | HL7: 21.4113 | HM7: 21.8552 | HN7: 21.9461 | HO7: 21.859 | HP7: 21.5691 | HQ7: 21.3325 | HR7: 23.4375 | HS7: 21.2588 | HT7: 21.569 | HU7: 20.4263 | HV7: 20.8849 | HW7: 22.6194 | HX7: 22.6653 | HY7: 23.0667 | HZ7: 22.7892 | IA7: 23.3243 | IB7: 22.7892 | IC7: 22.975 | ID7: 22.9062
A8: 7 | B8: 1.8613 | C8: 1.8474 | D8: 1.8486 | E8: 1.8354 | F8: 1.8035 | G8: 1.7572 | H8: 1.7479 | I8: 1.9148 | J8: 1.874 | K8: 1.9641 | L8: 1.9162 | M8: 1.9586 | N8: 1.8849 | O8: 1.8276 | P8: 1.8203 | Q8: 1.8089 | R8: 1.8963 | S8: 1.8899 | T8: 1.9103 | U8: 1.8221 | V8: 1.8022 | W8: 1.7722 | X8: 1.7879 | Y8: 1.8175 | Z8: 1.7536 | AA8: 1.7719 | AB8: 1.7755 | AC8: 1.8328 | AD8: 1.9789 | AE8: 1.8461 | AF8: 1.8589 | AG8: 1.8596 | AH8: 1.9934 | AI8: 1.8479 | AJ8: 1.8489 | AK8: 1.9371 | AL8: 1.8698 | AM8: 1.8263 | AN8: 1.8677 | AO8: 1.8644 | AP8: 1.9248 | AQ8: 1.8164 | AR8: 1.9214 | AS8: 1.9302 | AT8: 2.0074 | AU8: 1.8584 | AV8: 2.0359 | AW8: 2.0318 | AX8: 1.7889 | AY8: 1.9377 | AZ8: 1.8946 | BA8: 1.9159 | BB8: 2.0133 | BC8: 1.9989 | BD8: 1.9718 | BE8: 1.924 | BF8: 1.882 | BG8: 1.9464 | BH8: 1.8301 | BI8: 2.0662 | BJ8: 1.996 | BK8: 1.9991 | BL8: 1.9516 | BM8: 1.9537 | BN8: 1.9615 | BO8: 1.9846 | BP8: 1.9877 | BQ8: 2.0433 | BR8: 2.0077 | BS8: 2.0127 | BT8: 2.0181 | BU8: 2.0297 | BV8: 2.0264 | BW8: 1.9964 | BX8: 1.8788 | BY8: 1.8265 | BZ8: 1.867 | CA8: 1.9807 | CB8: 1.9626 | CC8: 1.8249 | CD8: 1.8588 | CE8: 1.9008 | CF8: 1.8703 | CG8: 1.8727 | CH8: 1.876 | CI8: 1.8784 | CJ8: 1.8798 | CK8: 1.8778 | CL8: 1.8758 | CM8: 1.9183 | CN8: 1.8755 | CO8: 1.8677 | CP8: 1.8653 | CQ8: 1.8556 | CR8: 1.845 | CS8: 1.837 | CT8: 1.8578 | CU8: 1.8291 | CV8: 0 | CW8: 1.9152 | CX8: 1.9337 | CY8: 1.8727 | CZ8: 1.8232 | DA8: 1.8353 | DB8: 1.9075 | DC8: 1.9058 | DD8: 1.9559 | DE8: 1.9873 | DF8: 1.9916 | DG8: 1.8503 | DH8: 1.8809 | DI8: 2.0064 | DJ8: 1.9617 | DK8: 1.8914 | DL8: 1.749 | DM8: 1.7426 | DN8: 1.9464 | DO8: 1.8225 | DP8: 1.8663 | DQ8: 1.9242 | DR8: 2.0181 | DS8: 1.8731 | DT8: 1.8775 | DU8: 1.8418 | DV8: 1.8463 | DW8: 1.8458 | DX8: 1.9632 | DY8: 1.978 | DZ8: 1.832 | EA8: 1.8325 | EB8: 1.8441 | EC8: 1.7946 | ED8: 1.6512 | EE8: 1.8865 | EF8: 1.8612 | EG8: 1.847 | EH8: 1.8741 | EI8: 1.8767 | EJ8: 1.8786 | EK8: 1.8672 | EL8: 1.7172 | EM8: 1.7322 | EN8: 1.8267 | EO8: 1.8098 | EP8: 2.0181 | EQ8: 1.8219 | ER8: 1.83 | ES8: 1.8112 | ET8: 1.9793 | EU8: 1.9835 | EV8: 1.9682 | EW8: 1.9794 | EX8: 1.9451 | EY8: 1.8558 | EZ8: 1.9022 | FA8: 1.7865 | FB8: 1.8414 | FC8: 1.8294 | FD8: 1.8594 | FE8: 1.8612 | FF8: 1.9807 | FG8: 0 | FH8: 1.9463 | FI8: 1.8358 | FJ8: 1.8969 | FK8: 1.9156 | FL8: 1.8625 | FM8: 1.8604 | FN8: 1.9659 | FO8: 1.8891 | FP8: 1.8759 | FQ8: 1.7899 | FR8: 1.6522 | FS8: 1.9161 | FT8: 1.6545 | FU8: 1.7568 | FV8: 1.8313 | FW8: 1.8824 | FX8: 2.0337 | FY8: 2.0434 | FZ8: 1.9932 | GA8: 1.8958 | GB8: 1.815 | GC8: 1.9463 | GD8: 1.9422 | GE8: 1.9759 | GF8: 1.6851 | GG8: 1.9819 | GH8: 1.7507 | GI8: 1.7805 | GJ8: 1.7723 | GK8: 1.9578 | GL8: 2.0227 | GM8: 1.7585 | GN8: 2.0302 | GO8: 2.0458 | GP8: 2.0464 | GQ8: 2.0376 | GR8: 2.0181 | GS8: 2.0454 | GT8: 2.037 | GU8: 2.0464 | GV8: 2.0465 | GW8: 2.0445 | GX8: 2.012 | GY8: 1.8755 | GZ8: 1.8451 | HA8: 1.8612 | HB8: 0 | HC8: 1.8867 | HD8: 1.8742 | HE8: 1.8867 | HF8: 1.8334 | HG8: 1.8366 | HH8: 1.8642 | HI8: 1.8889 | HJ8: 1.9073 | HK8: 1.9916 | HL8: 1.8589 | HM8: 1.9003 | HN8: 1.9073 | HO8: 1.9007 | HP8: 1.8759 | HQ8: 1.8529 | HR8: 2.0386 | HS8: 1.8477 | HT8: 1.8759 | HU8: 1.7755 | HV8: 1.8159 | HW8: 1.9661 | HX8: 1.9701 | HY8: 2.0051 | HZ8: 1.9807 | IA8: 2.0246 | IB8: 1.9807 | IC8: 1.997 | ID8: 1.9911
A9: 8 | B9: 1.8609 | C9: 1.8464 | D9: 1.8477 | E9: 1.835 | F9: 1.8033 | G9: 1.7566 | H9: 1.7472 | I9: 1.9146 | J9: 1.8734 | K9: 1.9639 | L9: 1.9156 | M9: 1.9584 | N9: 1.8845 | O9: 1.8272 | P9: 1.8192 | Q9: 1.8082 | R9: 1.8947 | S9: 1.8885 | T9: 1.9099 | U9: 1.8218 | V9: 1.8016 | W9: 1.7717 | X9: 1.7874 | Y9: 1.8169 | Z9: 1.7531 | AA9: 1.7715 | AB9: 1.7751 | AC9: 1.8324 | AD9: 1.9784 | AE9: 1.8452 | AF9: 1.8581 | AG9: 1.8588 | AH9: 1.9929 | AI9: 1.8475 | AJ9: 1.8485 | AK9: 1.9366 | AL9: 1.8692 | AM9: 1.8259 | AN9: 1.867 | AO9: 1.864 | AP9: 1.9245 | AQ9: 1.8162 | AR9: 1.9207 | AS9: 1.9299 | AT9: 2.0068 | AU9: 1.8559 | AV9: 2.0356 | AW9: 2.0315 | AX9: 1.7882 | AY9: 1.9376 | AZ9: 1.8944 | BA9: 1.9138 | BB9: 2.0133 | BC9: 1.9984 | BD9: 1.9712 | BE9: 1.9221 | BF9: 1.8809 | BG9: 1.946 | BH9: 1.8275 | BI9: 2.0669 | BJ9: 1.9954 | BK9: 1.9985 | BL9: 1.9511 | BM9: 1.9532 | BN9: 1.9615 | BO9: 1.984 | BP9: 1.9871 | BQ9: 2.0423 | BR9: 2.0071 | BS9: 2.0121 | BT9: 2.0179 | BU9: 2.0288 | BV9: 2.0264 | BW9: 1.9957 | BX9: 1.8759 | BY9: 1.8255 | BZ9: 1.8655 | CA9: 1.9802 | CB9: 1.9622 | CC9: 1.8245 | CD9: 1.8582 | CE9: 1.8992 | CF9: 1.8696 | CG9: 1.872 | CH9: 1.8753 | CI9: 1.8778 | CJ9: 1.879 | CK9: 1.8771 | CL9: 1.8751 | CM9: 1.918 | CN9: 1.8748 | CO9: 1.867 | CP9: 1.8646 | CQ9: 1.8549 | CR9: 1.8443 | CS9: 1.8368 | CT9: 1.8575 | CU9: 1.8289 | CV9: 0 | CW9: 1.9147 | CX9: 1.9332 | CY9: 1.872 | CZ9: 1.8226 | DA9: 1.835 | DB9: 1.907 | DC9: 1.9052 | DD9: 1.9553 | DE9: 1.9866 | DF9: 1.9909 | DG9: 1.8496 | DH9: 1.8801 | DI9: 2.0062 | DJ9: 1.9613 | DK9: 1.8906 | DL9: 1.7479 | DM9: 1.742 | DN9: 1.9452 | DO9: 1.8221 | DP9: 1.8657 | DQ9: 1.9224 | DR9: 2.0176 | DS9: 1.8723 | DT9: 1.8767 | DU9: 1.8408 | DV9: 1.8437 | DW9: 1.8453 | DX9: 1.9631 | DY9: 1.9773 | DZ9: 1.8294 | EA9: 1.8299 | EB9: 1.8428 | EC9: 1.7939 | ED9: 1.6507 | EE9: 1.8862 | EF9: 1.8603 | EG9: 1.8465 | EH9: 1.8735 | EI9: 1.876 | EJ9: 1.878 | EK9: 1.8647 | EL9: 1.7166 | EM9: 1.7316 | EN9: 1.8261 | EO9: 1.8092 | EP9: 2.0175 | EQ9: 1.8219 | ER9: 1.8294 | ES9: 1.8106 | ET9: 1.9786 | EU9: 1.9829 | EV9: 1.9678 | EW9: 1.9789 | EX9: 1.9448 | EY9: 1.8549 | EZ9: 1.9011 | FA9: 1.7885 | FB9: 1.8385 | FC9: 1.8279 | FD9: 1.8587 | FE9: 1.8606 | FF9: 1.9801 | FG9: 0 | FH9: 1.9457 | FI9: 1.8354 | FJ9: 1.8967 | FK9: 1.9153 | FL9: 1.8619 | FM9: 1.8598 | FN9: 1.9657 | FO9: 1.8881 | FP9: 1.8752 | FQ9: 1.7896 | FR9: 1.6521 | FS9: 1.9156 | FT9: 1.6544 | FU9: 1.7573 | FV9: 1.8309 | FW9: 1.8822 | FX9: 2.0331 | FY9: 2.0425 | FZ9: 1.9927 | GA9: 1.8956 | GB9: 1.8143 | GC9: 1.9459 | GD9: 1.9418 | GE9: 1.9752 | GF9: 1.6852 | GG9: 1.9816 | GH9: 1.7499 | GI9: 1.7799 | GJ9: 1.7719 | GK9: 1.9575 | GL9: 2.0222 | GM9: 1.758 | GN9: 2.0303 | GO9: 2.0454 | GP9: 2.0461 | GQ9: 2.0373 | GR9: 2.0175 | GS9: 2.0451 | GT9: 2.0361 | GU9: 2.0455 | GV9: 2.0462 | GW9: 2.0444 | GX9: 2.0115 | GY9: 1.8748 | GZ9: 1.8443 | HA9: 1.8606 | HB9: 0 | HC9: 1.8857 | HD9: 1.8735 | HE9: 1.8857 | HF9: 1.8328 | HG9: 1.836 | HH9: 1.8635 | HI9: 1.8876 | HJ9: 1.9068 | HK9: 1.9912 | HL9: 1.8581 | HM9: 1.9001 | HN9: 1.9068 | HO9: 1.9006 | HP9: 1.875 | HQ9: 1.8523 | HR9: 2.0388 | HS9: 1.8466 | HT9: 1.875 | HU9: 1.775 | HV9: 1.8156 | HW9: 1.9657 | HX9: 1.9697 | HY9: 2.0045 | HZ9: 1.9801 | IA9: 2.025 | IB9: 1.9801 | IC9: 1.9964 | ID9: 1.9904
A10: 9 | B10: 3.6375 | C10: 3.6182 | D10: 3.621 | E10: 3.5891 | F10: 3.5173 | G10: 3.4359 | H10: 3.418 | I10: 3.7452 | J10: 3.6671 | K10: 3.8415 | L10: 3.7486 | M10: 3.8314 | N10: 3.687 | O10: 3.576 | P10: 3.562 | Q10: 3.5395 | R10: 3.7124 | S10: 3.6998 | T10: 3.7396 | U10: 3.5707 | V10: 3.5249 | W10: 3.4666 | X10: 3.4971 | Y10: 3.5553 | Z10: 3.4287 | AA10: 3.4638 | AB10: 3.4707 | AC10: 3.5857 | AD10: 3.8689 | AE10: 3.6157 | AF10: 3.6394 | AG10: 3.642 | AH10: 3.8966 | AI10: 3.6113 | AJ10: 3.6136 | AK10: 3.789 | AL10: 3.6589 | AM10: 3.5704 | AN10: 3.6549 | AO10: 3.6435 | AP10: 3.7607 | AQ10: 3.5531 | AR10: 3.7584 | AS10: 3.7712 | AT10: 3.9237 | AU10: 3.6352 | AV10: 3.9846 | AW10: 3.9767 | AX10: 3.5002 | AY10: 3.7917 | AZ10: 3.7076 | BA10: 3.748 | BB10: 3.9376 | BC10: 3.9118 | BD10: 3.8589 | BE10: 3.7642 | BF10: 3.685 | BG10: 3.8088 | BH10: 3.5797 | BI10: 4.0475 | BJ10: 3.9062 | BK10: 3.9125 | BL10: 3.8189 | BM10: 3.823 | BN10: 3.8372 | BO10: 3.8834 | BP10: 3.8894 | BQ10: 3.9976 | BR10: 3.9293 | BS10: 3.9393 | BT10: 3.948 | BU10: 3.9729 | BV10: 3.9677 | BW10: 3.9069 | BX10: 3.6746 | BY10: 3.579 | BZ10: 3.6571 | CA10: 3.8723 | CB10: 3.838 | CC10: 3.5687 | CD10: 3.6429 | CE10: 3.7208 | CF10: 3.6598 | CG10: 3.6645 | CH10: 3.6708 | CI10: 3.6756 | CJ10: 3.6781 | CK10: 3.6744 | CL10: 3.6704 | CM10: 3.7518 | CN10: 3.6712 | CO10: 3.6551 | CP10: 3.6509 | CQ10: 3.6326 | CR10: 3.6132 | CS10: 3.5933 | CT10: 3.6336 | CU10: 3.5789 | CV10: 0 | CW10: 3.7468 | CX10: 3.7825 | CY10: 3.6647 | CZ10: 3.567 | DA10: 3.5868 | DB10: 3.7336 | DC10: 3.7303 | DD10: 3.8276 | DE10: 3.8889 | DF10: 3.8974 | DG10: 3.6208 | DH10: 3.6816 | DI10: 3.9253 | DJ10: 3.8362 | DK10: 3.7019 | DL10: 3.4194 | DM10: 3.4084 | DN10: 3.7702 | DO10: 3.5615 | DP10: 3.6527 | DQ10: 3.7645 | DR10: 3.9495 | DS10: 3.6653 | DT10: 3.6739 | DU10: 3.6078 | DV10: 3.6114 | DW10: 3.6117 | DX10: 3.8399 | DY10: 3.8706 | DZ10: 3.5833 | EA10: 3.5842 | EB10: 3.6127 | EC10: 3.5118 | ED10: 3.2284 | EE10: 3.6895 | EF10: 3.6438 | EG10: 3.6135 | EH10: 3.6674 | EI10: 3.6724 | EJ10: 3.6761 | EK10: 3.6524 | EL10: 3.3575 | EM10: 3.387 | EN10: 3.5748 | EO10: 3.5417 | EP10: 3.9493 | EQ10: 3.5601 | ER10: 3.5815 | ES10: 3.5443 | ET10: 3.8731 | EU10: 3.8813 | EV10: 3.8485 | EW10: 3.8704 | EX10: 3.8038 | EY10: 3.6336 | EZ10: 3.7241 | FA10: 3.492 | FB10: 3.606 | FC10: 3.5806 | FD10: 3.6394 | FE10: 3.6429 | FF10: 3.8759 | FG10: 0 | FH10: 3.8086 | FI10: 3.5899 | FJ10: 3.7121 | FK10: 3.7484 | FL10: 3.6453 | FM10: 3.6411 | FN10: 3.845 | FO10: 3.6981 | FP10: 3.672 | FQ10: 3.5025 | FR10: 3.2328 | FS10: 3.7507 | FT10: 3.2374 | FU10: 3.4359 | FV10: 3.583 | FW10: 3.6787 | FX10: 3.9747 | FY10: 3.9937 | FZ10: 3.8962 | GA10: 3.7079 | GB10: 3.5515 | GC10: 3.8085 | GD10: 3.8005 | GE10: 3.8665 | GF10: 3.2968 | GG10: 3.8779 | GH10: 3.4232 | GI10: 3.4807 | GJ10: 3.4646 | GK10: 3.8261 | GL10: 3.9532 | GM10: 3.438 | GN10: 3.977 | GO10: 4.0039 | GP10: 4.0051 | GQ10: 3.9879 | GR10: 3.9493 | GS10: 4.0032 | GT10: 3.9855 | GU10: 4.0037 | GV10: 4.0054 | GW10: 4.0022 | GX10: 3.9378 | GY10: 3.6712 | GZ10: 3.6132 | HA10: 3.6429 | HB10: 0 | HC10: 3.6946 | HD10: 3.6673 | HE10: 3.6946 | HF10: 3.588 | HG10: 3.5945 | HH10: 3.649 | HI10: 3.6981 | HJ10: 3.734 | HK10: 3.8935 | HL10: 3.6393 | HM10: 3.721 | HN10: 3.7333 | HO10: 3.722 | HP10: 3.6741 | HQ10: 3.6259 | HR10: 3.9921 | HS10: 3.6164 | HT10: 3.674 | HU10: 3.4717 | HV10: 3.5533 | HW10: 3.8447 | HX10: 3.8523 | HY10: 3.9193 | HZ10: 3.8759 | IA10: 3.9666 | IB10: 3.8759 | IC10: 3.9073 | ID10: 3.8958
A11: 10 | B11: 1.8553 | C11: 1.846 | D11: 1.8473 | E11: 1.8335 | F11: 1.803 | G11: 1.7527 | H11: 1.7437 | I11: 1.9097 | J11: 1.8711 | K11: 1.959 | L11: 1.9119 | M11: 1.9541 | N11: 1.8833 | O11: 1.8239 | P11: 1.8168 | Q11: 1.8057 | R11: 1.8936 | S11: 1.8869 | T11: 1.9074 | U11: 1.8251 | V11: 1.7985 | W11: 1.7678 | X11: 1.7837 | Y11: 1.8144 | Z11: 1.7488 | AA11: 1.7668 | AB11: 1.7704 | AC11: 1.8286 | AD11: 1.9728 | AE11: 1.8447 | AF11: 1.8572 | AG11: 1.8581 | AH11: 1.9866 | AI11: 1.8419 | AJ11: 1.843 | AK11: 1.9323 | AL11: 1.8669 | AM11: 1.8207 | AN11: 1.8647 | AO11: 1.8583 | AP11: 1.9186 | AQ11: 1.8117 | AR11: 1.9169 | AS11: 1.924 | AT11: 2.0003 | AU11: 1.8527 | AV11: 2.0312 | AW11: 2.0271 | AX11: 1.7857 | AY11: 1.9317 | AZ11: 1.8886 | BA11: 1.9099 | BB11: 2.0073 | BC11: 1.9947 | BD11: 1.9666 | BE11: 1.9181 | BF11: 1.8794 | BG11: 1.941 | BH11: 1.8247 | BI11: 2.0638 | BJ11: 1.9915 | BK11: 1.9947 | BL11: 1.9462 | BM11: 1.9484 | BN11: 1.9572 | BO11: 1.9801 | BP11: 1.9833 | BQ11: 2.0376 | BR11: 2.0035 | BS11: 2.0088 | BT11: 2.0116 | BU11: 2.0259 | BV11: 2.0234 | BW11: 1.9919 | BX11: 1.8734 | BY11: 1.8259 | BZ11: 1.8652 | CA11: 1.9746 | CB11: 1.9572 | CC11: 1.8199 | CD11: 1.8592 | CE11: 1.8975 | CF11: 1.8674 | CG11: 1.8698 | CH11: 1.873 | CI11: 1.8755 | CJ11: 1.8767 | CK11: 1.8748 | CL11: 1.8728 | CM11: 1.913 | CN11: 1.8727 | CO11: 1.8648 | CP11: 1.8627 | CQ11: 1.8534 | CR11: 1.8434 | CS11: 1.8322 | CT11: 1.8528 | CU11: 1.825 | CV11: 0 | CW11: 1.911 | CX11: 1.929 | CY11: 1.8698 | CZ11: 1.82 | DA11: 1.8295 | DB11: 1.9044 | DC11: 1.9027 | DD11: 1.9519 | DE11: 1.9828 | DF11: 1.9871 | DG11: 1.8473 | DH11: 1.878 | DI11: 2 | DJ11: 1.9562 | DK11: 1.888 | DL11: 1.7444 | DM11: 1.7377 | DN11: 1.9377 | DO11: 1.8167 | DP11: 1.8641 | DQ11: 1.9183 | DR11: 2.0134 | DS11: 1.8701 | DT11: 1.8743 | DU11: 1.8406 | DV11: 1.8407 | DW11: 1.8423 | DX11: 1.9582 | DY11: 1.9735 | DZ11: 1.8266 | EA11: 1.8271 | EB11: 1.8429 | EC11: 1.7916 | ED11: 1.6467 | EE11: 1.8814 | EF11: 1.8594 | EG11: 1.843 | EH11: 1.8712 | EI11: 1.8736 | EJ11: 1.8754 | EK11: 1.8612 | EL11: 1.7128 | EM11: 1.7278 | EN11: 1.824 | EO11: 1.8071 | EP11: 2.0133 | EQ11: 1.8206 | ER11: 1.8272 | ES11: 1.8082 | ET11: 1.9748 | EU11: 1.979 | EV11: 1.9622 | EW11: 1.9733 | EX11: 1.9396 | EY11: 1.8541 | EZ11: 1.8994 | FA11: 1.7839 | FB11: 1.8379 | FC11: 1.826 | FD11: 1.8569 | FE11: 1.8592 | FF11: 1.9762 | FG11: 0 | FH11: 1.9416 | FI11: 1.834 | FJ11: 1.8909 | FK11: 1.9097 | FL11: 1.8605 | FM11: 1.8584 | FN11: 1.9607 | FO11: 1.8861 | FP11: 1.8731 | FQ11: 1.7822 | FR11: 1.6455 | FS11: 1.9129 | FT11: 1.6478 | FU11: 1.7482 | FV11: 1.8273 | FW11: 1.8761 | FX11: 2.0265 | FY11: 2.036 | FZ11: 1.9864 | GA11: 1.8907 | GB11: 1.8119 | GC11: 1.9408 | GD11: 1.9367 | GE11: 1.9708 | GF11: 1.6779 | GG11: 1.9776 | GH11: 1.7463 | GI11: 1.7753 | GJ11: 1.7672 | GK11: 1.9506 | GL11: 2.0155 | GM11: 1.7534 | GN11: 2.0275 | GO11: 2.0411 | GP11: 2.0417 | GQ11: 2.0328 | GR11: 2.0133 | GS11: 2.0407 | GT11: 2.0315 | GU11: 2.0407 | GV11: 2.0419 | GW11: 2.0403 | GX11: 2.0075 | GY11: 1.8727 | GZ11: 1.8434 | HA11: 1.8592 | HB11: 0 | HC11: 1.8849 | HD11: 1.8713 | HE11: 1.8849 | HF11: 1.8307 | HG11: 1.8339 | HH11: 1.8617 | HI11: 1.8861 | HJ11: 1.9047 | HK11: 1.9852 | HL11: 1.8571 | HM11: 1.8982 | HN11: 1.9042 | HO11: 1.8987 | HP11: 1.8748 | HQ11: 1.8497 | HR11: 2.0357 | HS11: 1.8445 | HT11: 1.8748 | HU11: 1.7706 | HV11: 1.8103 | HW11: 1.9605 | HX11: 1.9644 | HY11: 1.998 | HZ11: 1.9762 | IA11: 2.0222 | IB11: 1.9762 | IC11: 1.992 | ID11: 1.9863
A12: 11 | B12: 21.5122 | C12: 21.3758 | D12: 21.3972 | E12: 21.1187 | F12: 20.6493 | G12: 20.2695 | H12: 20.1612 | I12: 22.1401 | J12: 21.6017 | K12: 22.7159 | L12: 22.126 | M12: 22.6525 | N12: 21.7217 | O12: 21.0929 | P12: 21.0231 | Q12: 20.8766 | R12: 21.9534 | S12: 21.8734 | T12: 22.0744 | U12: 21.0945 | V12: 20.779 | W12: 20.4267 | X12: 20.6086 | Y12: 20.9557 | Z12: 20.2302 | AA12: 20.4412 | AB12: 20.4846 | AC12: 21.1568 | AD12: 22.8794 | AE12: 21.3602 | AF12: 21.4568 | AG12: 21.4803 | AH12: 23.0483 | AI12: 21.3541 | AJ12: 21.363 | AK12: 22.3795 | AL12: 21.5552 | AM12: 21.0826 | AN12: 21.5358 | AO12: 21.5493 | AP12: 22.2794 | AQ12: 20.9833 | AR12: 22.1834 | AS12: 22.3451 | AT12: 23.2124 | AU12: 21.4841 | AV12: 23.5359 | AW12: 23.4875 | AX12: 20.6448 | AY12: 22.397 | AZ12: 21.8961 | BA12: 22.1654 | BB12: 23.2639 | BC12: 23.1054 | BD12: 22.8181 | BE12: 22.2616 | BF12: 21.7919 | BG12: 22.4996 | BH12: 21.1514 | BI12: 23.8961 | BJ12: 23.0717 | BK12: 23.1091 | BL12: 22.5559 | BM12: 22.5791 | BN12: 22.6753 | BO12: 22.937 | BP12: 22.9737 | BQ12: 23.6099 | BR12: 23.2102 | BS12: 23.2706 | BT12: 23.3282 | BU12: 23.4609 | BV12: 23.4334 | BW12: 23.0756 | BX12: 21.7036 | BY12: 21.1667 | BZ12: 21.6191 | CA12: 22.902 | CB12: 22.6865 | CC12: 21.0684 | CD12: 21.2884 | CE12: 21.9989 | CF12: 21.5607 | CG12: 21.5882 | CH12: 21.6235 | CI12: 21.6529 | CJ12: 21.6707 | CK12: 21.6463 | CL12: 21.6229 | CM12: 22.174 | CN12: 21.63 | CO12: 21.5364 | CP12: 21.5149 | CQ12: 21.4012 | CR12: 21.3157 | CS12: 21.224 | CT12: 21.4624 | CU12: 21.1181 | CV12: 0 | CW12: 22.1162 | CX12: 22.3391 | CY12: 21.595 | CZ12: 21.0343 | DA12: 21.2066 | DB12: 22.0328 | DC12: 22.0137 | DD12: 22.5994 | DE12: 22.9687 | DF12: 23.0193 | DG12: 21.341 | DH12: 21.6925 | DI12: 23.1927 | DJ12: 22.6752 | DK12: 21.8116 | DL12: 20.1673 | DM12: 20.0923 | DN12: 22.2015 | DO12: 21.0515 | DP12: 21.4995 | DQ12: 22.2612 | DR12: 23.3271 | DS12: 21.5997 | DT12: 21.6504 | DU12: 21.3228 | DV12: 21.3409 | DW12: 21.2973 | DX12: 22.7061 | DY12: 22.8583 | DZ12: 21.1726 | EA12: 21.1781 | EB12: 21.3625 | EC12: 20.7124 | ED12: 19.0484 | EE12: 21.8008 | EF12: 21.4839 | EG12: 21.3226 | EH12: 21.607 | EI12: 21.6413 | EJ12: 21.6616 | EK12: 21.5868 | EL12: 19.8097 | EM12: 19.9821 | EN12: 21.0713 | EO12: 20.8761 | EP12: 23.3256 | EQ12: 20.9233 | ER12: 21.1227 | ES12: 20.9042 | ET12: 22.8754 | EU12: 22.924 | EV12: 22.7589 | EW12: 22.8898 | EX12: 22.4894 | EY12: 21.4334 | EZ12: 21.9329 | FA12: 20.5795 | FB12: 21.3122 | FC12: 21.1442 | FD12: 21.4441 | FE12: 21.4369 | FF12: 22.8894 | FG12: 0 | FH12: 22.4854 | FI12: 21.1225 | FJ12: 21.9234 | FK12: 22.1404 | FL12: 21.4521 | FM12: 21.4298 | FN12: 22.7328 | FO12: 21.7826 | FP12: 21.6346 | FQ12: 20.6686 | FR12: 19.0794 | FS12: 22.1397 | FT12: 19.1066 | FU12: 20.2566 | FV12: 21.1378 | FW12: 21.7597 | FX12: 23.5299 | FY12: 23.6355 | FZ12: 23.0462 | GA12: 21.9112 | GB12: 20.9451 | GC12: 22.4966 | GD12: 22.448 | GE12: 22.8373 | GF12: 19.4562 | GG12: 22.9109 | GH12: 20.1923 | GI12: 20.5387 | GJ12: 20.4461 | GK12: 22.6382 | GL12: 23.4012 | GM12: 20.2822 | GN12: 23.4952 | GO12: 23.652 | GP12: 23.6591 | GQ12: 23.5551 | GR12: 23.3245 | GS12: 23.6477 | GT12: 23.536 | GU12: 23.6462 | GV12: 23.6607 | GW12: 23.6425 | GX12: 23.2579 | GY12: 21.63 | GZ12: 21.3158 | HA12: 21.437 | HB12: 0 | HC12: 21.8489 | HD12: 21.603 | HE12: 21.8489 | HF12: 21.1495 | HG12: 21.1901 | HH12: 21.5014 | HI12: 21.8691 | HJ12: 22.0477 | HK12: 23.0287 | HL12: 21.4567 | HM12: 21.969 | HN12: 22.0311 | HO12: 21.9763 | HP12: 21.7383 | HQ12: 21.3729 | HR12: 23.5738 | HS12: 21.3588 | HT12: 21.7382 | HU12: 20.4875 | HV12: 20.9881 | HW12: 22.7281 | HX12: 22.7755 | HY12: 23.1859 | HZ12: 22.8894 | IA12: 23.4334 | IB12: 22.8894 | IC12: 23.0789 | ID12: 23.011
A13: 12 | B13: 22.7776 | C13: 22.633 | D13: 22.6561 | E13: 22.3819 | F13: 21.8882 | G13: 21.4606 | H13: 21.3485 | I13: 23.4732 | J13: 22.8774 | K13: 24.0977 | L13: 23.4511 | M13: 24.0319 | N13: 23.0139 | O13: 22.3302 | P13: 22.2459 | Q13: 22.0951 | R13: 23.2394 | S13: 23.1528 | T13: 23.3404 | U13: 22.3477 | V13: 22 | W13: 21.6166 | X13: 21.8122 | Y13: 22.1903 | Z13: 21.4183 | AA13: 21.6419 | AB13: 21.6873 | AC13: 22.3995 | AD13: 24.2648 | AE13: 22.616 | AF13: 22.7363 | AG13: 22.7611 | AH13: 24.4446 | AI13: 22.6117 | AJ13: 22.6201 | AK13: 23.7268 | AL13: 22.8256 | AM13: 22.3252 | AN13: 22.8021 | AO13: 22.8167 | AP13: 23.5875 | AQ13: 22.2219 | AR13: 23.5136 | AS13: 23.6569 | AT13: 24.6195 | AU13: 22.6356 | AV13: 24.8149 | AW13: 24.769 | AX13: 21.8447 | AY13: 23.6258 | AZ13: 23.0947 | BA13: 23.3355 | BB13: 24.582 | BC13: 24.3725 | BD13: 24.0193 | BE13: 23.4304 | BF13: 23.0627 | BG13: 23.7295 | BH13: 22.3039 | BI13: 25.0909 | BJ13: 24.3302 | BK13: 24.37 | BL13: 23.7893 | BM13: 23.8139 | BN13: 24.0199 | BO13: 24.2056 | BP13: 24.2472 | BQ13: 24.8982 | BR13: 24.4573 | BS13: 24.5078 | BT13: 24.6186 | BU13: 24.6833 | BV13: 24.6602 | BW13: 24.3344 | BX13: 22.9069 | BY13: 22.399 | BZ13: 22.8832 | CA13: 24.2892 | CB13: 24.059 | CC13: 22.3097 | CD13: 22.7318 | CE13: 23.2871 | CF13: 22.8311 | CG13: 22.8595 | CH13: 22.9005 | CI13: 22.9302 | CJ13: 22.9468 | CK13: 22.9225 | CL13: 22.8972 | CM13: 23.5017 | CN13: 22.9065 | CO13: 22.804 | CP13: 22.7879 | CQ13: 22.6612 | CR13: 22.5658 | CS13: 22.4732 | CT13: 22.7322 | CU13: 22.3568 | CV13: 0 | CW13: 23.4408 | CX13: 23.6828 | CY13: 22.8581 | CZ13: 22.2715 | DA13: 22.4579 | DB13: 23.2906 | DC13: 23.2701 | DD13: 23.8537 | DE13: 24.2252 | DF13: 24.2758 | DG13: 22.594 | DH13: 22.9743 | DI13: 24.4735 | DJ13: 24.0461 | DK13: 23.1024 | DL13: 21.3559 | DM13: 21.2633 | DN13: 23.4796 | DO13: 22.2979 | DP13: 22.7923 | DQ13: 23.4296 | DR13: 24.5929 | DS13: 22.8701 | DT13: 22.9214 | DU13: 22.5706 | DV13: 22.4941 | DW13: 22.5412 | DX13: 24.0875 | DY13: 24.1111 | DZ13: 22.3266 | EA13: 22.3324 | EB13: 22.6072 | EC13: 21.9181 | ED13: 20.1671 | EE13: 23.0972 | EF13: 22.7651 | EG13: 22.5412 | EH13: 22.8763 | EI13: 22.9141 | EJ13: 22.936 | EK13: 22.7346 | EL13: 20.9763 | EM13: 21.1573 | EN13: 22.3087 | EO13: 22.1021 | EP13: 24.5916 | EQ13: 22.1753 | ER13: 22.3534 | ES13: 22.121 | ET13: 24.1362 | EU13: 24.192 | EV13: 24.1057 | EW13: 24.2447 | EX13: 23.8283 | EY13: 22.7071 | EZ13: 23.2181 | FA13: 21.7813 | FB13: 22.5419 | FC13: 22.37 | FD13: 22.7151 | FE13: 22.7315 | FF13: 24.1404 | FG13: 0 | FH13: 23.8071 | FI13: 22.3864 | FJ13: 23.1238 | FK13: 23.3543 | FL13: 22.7466 | FM13: 22.7236 | FN13: 24.1147 | FO13: 23.0626 | FP13: 22.9113 | FQ13: 21.7947 | FR13: 20.1013 | FS13: 23.4112 | FT13: 20.131 | FU13: 21.2301 | FV13: 22.3788 | FW13: 23.0325 | FX13: 24.8775 | FY13: 24.9938 | FZ13: 24.4423 | GA13: 23.2167 | GB13: 22.1687 | GC13: 23.727 | GD13: 23.6761 | GE13: 24.0845 | GF13: 20.4628 | GG13: 24.2104 | GH13: 21.381 | GI13: 21.7476 | GJ13: 21.647 | GK13: 23.9427 | GL13: 24.7416 | GM13: 21.4693 | GN13: 24.7784 | GO13: 24.9382 | GP13: 24.9457 | GQ13: 24.8333 | GR13: 24.5784 | GS13: 24.9336 | GT13: 24.8171 | GU13: 24.9367 | GV13: 24.9474 | GW13: 24.9287 | GX13: 24.5077 | GY13: 22.9065 | GZ13: 22.5659 | HA13: 22.7317 | HB13: 0 | HC13: 23.1323 | HD13: 22.8788 | HE13: 23.1323 | HF13: 22.3913 | HG13: 22.435 | HH13: 22.771 | HI13: 23.1465 | HJ13: 23.3189 | HK13: 24.4236 | HL13: 22.7361 | HM13: 23.2304 | HN13: 23.289 | HO13: 23.2417 | HP13: 23.0242 | HQ13: 22.6285 | HR13: 24.7571 | HS13: 22.6039 | HT13: 23.0241 | HU13: 21.692 | HV13: 22.1387 | HW13: 24.1028 | HX13: 24.1534 | HY13: 24.5912 | HZ13: 24.1401 | IA13: 24.7128 | IB13: 24.1381 | IC13: 24.3489 | ID13: 24.2819
